#BASICS

weight=7
unique=0
embed_into_distance=6
acceptable_target_blocks=1,2,3,12,13,49,79,110
dimensions=13,7,7
allowable_overhang=2
max_cut_in=2
cut_in_buffer=1
max_leveling=2
leveling_buffer=1
preserve_water=0
preserve_lava=0
preserve_plants=0


# RULES LIST, SETS BLOCK NUMBERS

rule1=0,100,24
rule2=0,100,49
rule3=0,100,1
rule4=0,100,89
rule5=0,100,11
rule6=0,100,57
rule7=0,100,47
rule8=0,100,30
rule9=0,100,307

# MY LIST OF BLOCKS

#     0 = AIR
#     2 = Obsidian
#     1 = Sandstone
#     3 = Stone
#     4 = Glowstone
#     5 = Lava
#     6 = Diamond
#     7 = Bookcase
#     8 = Cobweb
#     9 = spawner

# SPECIAL BLOCK IDS
#     300 = Leave existing world block alone
#     301 = Mob Spawner (Zombie)
#     302 = Mob Spawner (Skeleton) 
#     303 = Mob Spawner (Spider)
#     304 = Mob Spawner (Creeper)
#     305 = Mob Spawner (Zombie, Skeleton, Creeper)
#     306 = Mob Spawner (Easy, zombies and skeletons)
#     307 = Mob Spawner (Medium, zombies, skeletons, and spiders)
#     308 = Mob Spawner (Hard, all mobs)
#     309 = Easy Chest (For Easy rewards)
#     310 = Medium Chest (For Medium rewards)
#     311 = Hard Chest (For Hard rewards)
# LAYERS
# FOUNDATION 1, 2, 3

layer
1,1,1,1,1,1,1
1,1,1,1,1,1,1
1,1,1,1,1,1,1
1,1,1,1,1,1,1
1,1,1,1,1,1,1
1,1,1,1,1,1,1
1,1,1,1,1,1,1
endlayer

layer
1,1,1,1,1,1,1
1,5,5,5,5,5,1
1,5,5,5,5,5,1
1,5,5,1,5,5,1
1,5,5,5,5,5,1
1,5,5,5,5,5,1
1,1,1,1,1,1,1
endlayer

layer
1,1,1,1,1,1,1
1,5,5,5,5,5,1
1,5,5,1,5,5,1
1,5,1,6,1,5,1
1,5,5,1,5,5,1
1,5,5,5,5,5,1
1,1,1,1,1,1,1
endlayer

# MAIN FLOOR 4, 5, 6, 7

layer
2,2,2,2,2,2,2
2,2,3,2,3,2,2
2,3,2,3,2,3,2
2,2,3,9,3,2,2
2,3,2,3,2,3,2
2,2,3,2,3,2,2
2,2,2,2,2,2,2
endlayer

layer
1,1,1,1,1,1,1
1,0,0,0,0,0,1
1,0,0,0,0,0,1
1,0,0,2,0,0,1
1,0,0,0,0,0,1
1,0,0,0,0,0,1
1,1,1,1,1,1,1
endlayer

layer
1,1,1,1,1,1,1
1,0,0,0,0,0,1
1,0,0,0,0,0,1
1,0,0,2,0,0,1
1,0,0,0,0,0,1
1,0,0,0,0,0,1
1,1,1,1,1,1,1
endlayer

layer
1,1,1,1,1,1,1
1,0,0,0,0,0,1
1,0,0,0,0,0,1
1,0,0,2,0,0,1
1,0,0,0,0,0,1
1,0,0,0,0,0,1
1,1,1,1,1,1,1
endlayer

#Second Floor; just the floor, Layer 8

layer
1,2,1,2,1,2,1
2,1,2,1,2,1,2
1,2,1,2,1,2,1
2,1,2,9,2,1,2
1,2,1,2,1,2,1
2,1,2,1,0,1,2
1,2,1,2,1,2,1
endlayer

#Second Floor, books and webs, layers 9, 10, 11

layer
1,2,1,2,1,2,1
2,9,0,0,0,0,2
1,7,7,7,7,0,1
2,0,0,7,0,0,2
1,7,0,7,0,7,1
2,0,8,0,0,7,2
1,2,1,2,1,2,1
endlayer

layer
1,2,1,2,1,2,1
2,0,0,0,0,0,2
1,7,7,7,7,0,1
2,0,0,7,0,0,2
1,7,0,7,8,7,1
2,0,0,0,0,0,2
1,2,1,2,1,2,1
endlayer

layer
1,2,1,2,1,2,1
2,0,0,0,0,0,2
1,7,7,7,7,8,1
2,0,0,7,0,0,2
1,7,0,7,0,7,1
2,8,0,0,0,0,2
1,2,1,2,1,2,1
endlayer

#Ceilingvault, Layer 12

layer
2,2,2,2,2,2,2
2,2,2,2,2,2,2
2,2,2,9,2,2,2
2,2,2,2,2,2,2
2,2,2,9,2,2,2
2,2,2,2,2,2,2
2,2,2,2,2,2,2
endlayer

#The Roof, Layer 13

layer
3,3,3,3,3,3,3
3,2,2,2,2,2,3
3,2,3,3,3,2,3
3,2,3,2,2,2,3
3,2,3,3,3,3,3
3,2,2,2,2,2,2
3,3,3,3,3,3,3
endlayer
