#BASICS

weight=6
unique=0
embed_into_distance=21
acceptable_target_blocks=1,2,3,9,12,13,49,79,110


#HIGH, WIDE (n-S), LONG (e-W)

dimensions=24,7,10

#FIDDLY BITS

allowable_overhang=10
max_cut_in=0
cut_in_buffer=1
max_leveling=2
leveling_buffer=0
preserve_water=0
preserve_lava=0
preserve_plants=0


#RULES LIST - SETS BLOCK NUMBERS

rule1=0,100,300
rule2=0,100,24
rule3=0,100,05
rule4=0,100,81
rule5=0,100,85
rule6=0,100,65-3
rule7=0,100,65-2
rule8=0,100,309
rule9=0,100,30
rule10=0,100,25
rule11=0,100,58
rule12=0,100,47
rule13=0,100,17
rule14=0,100,05
rule15=0,100,03
rule16=0,100,83
rule17=0,100,12
rule18=0,100,11
rule19=0,100,46
rule20=0,100,61
rule21=0,100,30
rule22=0,100,302
rule23=0,100,9
rule24=0,100,303
rule25=0,100,89

#MY LIST OF BLOCKS

#     0 = AIR
#     1 = Leave It Alone
#     2 = Sandstone
#     3 = Planks
#     4 = Cactus
#     5 = Fencepost
#     6 = Ladder (facing 3)
#     7 = Ladder (facing 2)
#     8 = EasyChest
#     9 = Cobweb
#     10 = Note Block
#     11 = Workbench
#     12 = Bookcase
#     13 = Logs
#     14 = Planks
#     15 = Dirt
#     16 = Sugar Cane
#     17 = Stonebrick
#     18 = Lava
#     19 = TNT
#     20 = Furnace
#     21 = web
#     22 = Skelly Spawner
#     23 = Water
#     25 = Glowstone

#SPECIAL BLOCK IDs (Put in Rule to make it go)


#     300 = Leave existing world block alone
#     301 = Mob Spawner (Zombie)
#     302 = Mob Spawner (Skeleton) 
#     303 = Mob Spawner (Spider)
#     304 = Mob Spawner (Creeper)
#     305 = Mob Spawner (Zombie, Skeleton, Creeper)
#     306 = Mob Spawner (Easy, zombies and skeletons)
#     307 = Mob Spawner (Medium, zombies, skeletons, and spiders)
#     308 = Mob Spawner (Hard, all mobs)
#     309 = Easy Chest (For Easy rewards)
#     310 = Medium Chest (For Medium rewards)
#     311 = Hard Chest (For Hard rewards)


# LAYERS
# Each layer is a comma-delimited list of rules, one for each block.  There
# must be as many layers as the height, and each layer must have "layer" before
# the rules and end with "endlayer".  There are as many rows as the length, and
# as many rules as the width.  If you want the block blanked out use 0, which
# represents the Air-block rule.


#Basement floor

layer
1,2,2,2,2,2,2,2,2,1
1,2,2,3,2,3,22,3,2,1
2,2,3,2,3,2,3,2,2,2
2,3,2,3,2,3,2,3,2,2
2,2,3,2,3,2,3,2,2,2
1,2,2,3,2,3,2,3,2,1
1,2,2,2,2,2,2,2,2,1
endlayer



#Basement, Layers -LIBRUM

layer
1,2,2,2,2,2,2,2,2,1
1,2,9,8,11,22,12,12,2,1
2,2,0,0,13,12,0,0,2,2
2,7,0,0,0,12,0,0,6,2
2,2,0,13,9,12,0,0,2,2
1,2,0,12,0,0,0,0,2,1
1,2,2,2,2,2,2,2,2,1
endlayer

layer
1,2,2,2,2,2,2,2,2,1
1,2,0,0,10,12,12,12,2,1
2,2,0,0,0,12,0,0,2,2
2,7,0,0,0,12,0,0,6,2
2,2,0,11,0,12,0,0,2,2
1,2,0,12,0,0,0,0,2,1
1,2,2,2,2,2,2,2,2,1
endlayer

layer
1,2,2,2,2,2,2,2,2,1
1,2,0,0,11,12,12,12,2,1
2,2,0,0,0,12,0,0,2,2
2,7,0,0,0,12,0,0,6,2
2,2,0,10,0,12,0,0,2,2
1,2,0,12,0,0,0,0,2,1
1,2,2,2,2,2,2,2,2,1
endlayer


#Basement Ceiling

layer
1,2,2,2,2,2,2,2,2,1
1,2,2,3,2,3,2,3,2,1
2,2,3,2,3,2,3,2,2,2
2,7,2,3,2,3,2,3,2,2
2,2,3,2,3,2,3,2,2,2
1,2,2,3,2,3,2,3,2,1
1,2,2,2,2,2,2,2,2,1
endlayer

#Spacer

layer
1,2,2,2,2,2,2,2,2,1
2,23,23,23,23,23,23,23,23,2
2,2,2,23,23,23,23,23,23,2
2,7,2,23,23,23,23,23,23,2
2,2,2,23,23,23,23,23,23,2
2,23,23,23,23,23,23,23,23,2
1,2,2,2,2,2,2,2,2,1
endlayer


# Midfloor Floor

layer
1,2,2,2,2,2,2,2,2,1
1,2,2,3,2,3,2,3,2,1
2,2,3,2,3,2,3,2,2,2
2,7,2,3,2,3,2,3,2,2
2,2,3,2,3,2,3,2,2,2
1,2,2,3,2,3,2,3,2,1
1,2,2,2,2,2,2,2,2,1
endlayer

#Midfloor, Layers - SPIDERS

layer
1,2,2,2,2,2,2,2,2,1
1,2,0,0,0,0,0,21,2,1
2,2,0,0,0,0,0,0,2,2
2,7,21,0,0,0,0,0,6,2
2,2,21,0,0,0,0,0,2,2
1,2,0,0,0,0,0,0,2,1
1,2,2,2,2,2,2,2,2,1
endlayer

layer
1,2,2,2,2,2,2,2,2,1
1,2,0,0,0,0,0,0,2,1
2,2,0,0,0,0,0,0,2,2
2,7,0,0,0,0,0,0,6,2
2,2,0,0,0,0,0,0,2,2
1,2,21,0,0,0,0,0,2,1
1,2,2,2,2,2,2,2,2,1
endlayer

layer
1,2,2,2,2,2,2,2,2,1
1,2,0,0,0,0,0,0,2,1
2,2,0,0,0,0,0,0,2,2
2,7,0,21,24,0,0,0,6,2
2,2,0,0,0,0,0,0,2,2
1,2,0,0,0,0,0,21,2,1
1,2,2,2,2,2,2,2,2,1
endlayer

#Midfloor Ceiling

layer
1,2,2,2,2,2,2,2,2,1
1,2,2,3,2,3,2,3,2,1
2,2,3,2,3,2,3,2,2,2
2,3,2,3,2,3,2,3,6,2
2,2,3,2,3,2,3,2,2,2
1,2,2,3,2,3,2,3,2,1
1,2,2,2,2,2,2,2,2,1
endlayer


#Spacer

layer
1,2,2,2,2,2,2,2,2,1
2,23,23,23,23,23,23,23,23,2
2,23,23,23,23,23,23,2,2,2
2,23,23,23,23,23,23,2,6,2
2,23,23,23,23,23,23,2,2,2
2,23,23,23,23,23,23,23,23,2
1,2,2,2,2,2,2,2,2,1
endlayer


#Topfloor Floor

layer
1,2,2,2,2,2,2,2,2,1
1,2,22,3,2,3,2,3,2,1
2,2,3,2,3,2,3,2,2,2
2,3,2,3,2,3,2,3,6,2
2,2,3,2,3,2,3,2,2,2
1,2,2,3,2,3,2,3,2,1
1,2,2,2,2,2,2,2,2,1
endlayer


layer
1,2,2,2,2,2,2,2,2,1
1,2,22,17,17,17,17,17,2,1
2,2,17,17,17,17,17,17,2,2
2,17,17,17,17,17,17,17,6,2
2,2,17,17,17,17,17,17,2,2
1,2,17,17,17,17,17,17,2,1
1,2,2,2,2,2,2,2,2,1
endlayer


TOPFLOOR - CACTUS


layer
1,2,2,2,2,2,2,2,2,1
1,2,2,2,0,4,4,4,2,1
2,2,2,4,0,0,0,4,2,2
2,7,0,4,0,4,0,0,6,2
2,2,0,4,0,4,0,0,2,2
1,2,0,0,0,4,0,0,2,1
1,2,2,2,2,2,2,2,2,1
endlayer

layer
1,2,2,2,2,2,2,2,2,1
1,2,2,2,0,4,4,4,2,1
2,2,2,4,0,0,0,4,2,2
2,7,0,4,0,4,0,0,6,2
2,2,0,4,0,4,0,0,2,2
1,2,0,0,0,4,0,0,2,1
1,2,2,2,2,2,2,2,2,1
endlayer

layer
1,2,2,2,2,2,2,2,2,1
1,2,2,2,0,4,4,4,2,1
2,2,2,4,0,0,0,4,2,2
2,7,0,4,0,4,0,0,6,2
2,2,0,4,0,4,0,0,2,2
1,2,0,0,0,4,0,0,2,1
1,2,2,2,2,2,2,2,2,1
endlayer


#Ceiling, Topfloor

layer
1,2,2,2,2,2,2,2,2,1
1,2,2,3,2,3,2,3,2,1
2,2,3,2,3,2,3,2,2,2
2,7,2,3,2,3,2,3,2,2
2,2,3,2,3,2,3,2,2,2
1,2,2,3,2,3,2,3,2,1
1,2,2,2,2,2,2,2,2,1
endlayer

# SPACER

layer
1,2,2,2,2,2,2,2,2,1
2,23,23,23,23,23,23,23,23,2
2,2,2,23,23,23,23,23,23,2
2,7,2,23,23,23,23,23,23,2
2,2,2,23,23,23,23,23,23,2
2,23,23,23,23,23,23,23,23,2
1,2,2,2,2,2,2,2,2,1
endlayer



#THE LID

layer
1,3,3,3,3,3,3,3,3,1
1,3,3,3,25,25,3,25,3,1
2,2,2,3,3,25,3,3,3,3
2,7,2,3,25,25,25,25,25,3
2,2,2,3,3,25,3,3,3,3
1,3,3,3,25,25,3,25,3,1
1,3,3,3,3,3,3,3,3,1
endlayer

layer
1,2,1,1,1,1,1,1,1,1
1,1,1,1,1,1,1,1,1,1
2,2,2,1,1,1,1,1,1,1
2,7,2,1,1,1,1,1,1,1
2,2,2,1,1,1,1,1,1,1
1,1,1,1,1,1,1,1,1,1
1,2,1,1,1,1,1,1,1,1
endlayer

layer
1,2,1,1,1,1,1,1,1,1
1,1,1,1,1,1,1,1,1,1
2,2,5,1,1,1,1,1,1,1
2,7,1,1,1,1,1,1,1,1
2,2,5,1,1,1,1,1,1,1
1,1,1,1,1,1,1,1,1,1
1,2,1,1,1,1,1,1,1,1
endlayer

layer
1,3,1,1,1,1,1,1,1,1
1,1,1,1,1,1,1,1,1,1
2,2,5,1,1,1,1,1,1,1
2,7,1,1,1,1,1,1,1,1
2,2,5,1,1,1,1,1,1,1
1,1,1,1,1,1,1,1,1,1
1,3,1,1,1,1,1,1,1,1
endlayer

layer
1,1,1,1,1,1,1,1,1,1
1,1,1,1,1,1,1,1,1,1
2,2,3,1,1,1,1,1,1,1
2,2,3,1,1,1,1,1,1,1
2,2,3,1,1,1,1,1,1,1
1,1,1,1,1,1,1,1,1,1
1,1,1,1,1,1,1,1,1,1
endlayer