#BASICS

weight=7
embed_into_distance=3
acceptable_target_blocks=1,2,3,12,13,49,79,110
dimensions=15,19,19
allowable_overhang=270
max_cut_in=5
cut_in_buffer=1
max_leveling=3
leveling_buffer=1
preserve_water=0
preserve_lava=0
preserve_plants=0


#RULES LIST - SETS BLOCK NUMBERS

rule1=0,100,49
rule2=0,100,24
rule3=0,100,49
rule4=0,100,5
rule5=0,100,309
rule6=0,100,8
rule7=0,100,47
rule8=0,100,5
rule9=0,100,44-2
rule10=0,100,9
rule11=0,100,25
rule12=0,100,302

#MY LIST OF BLOCKS

#     0 = AIR
#     1 = Obsidian
#     2 = Sandstone
#     3 = Obsidian
#     4 = Planks
#     5 = Chest
#     6 = Water
#     7 = Bookshelf
#     8 = Planks
#     9 = Plank-Slab
#     10 = Stationary Water
#     11 = Note Block
#     12 = Skellies

# THE BASEMENT

layer
2,2,2,2,2,2,2,2,2,2,2,2,2,2,2,2,2,2,2
2,4,4,4,4,4,4,4,4,4,4,4,4,4,4,4,4,4,2
2,4,4,4,4,4,4,4,4,4,4,4,4,4,4,4,4,4,2
2,4,4,4,4,4,4,4,4,4,4,4,4,4,4,4,4,4,2
2,4,4,4,4,4,4,4,4,4,4,4,4,4,4,4,4,4,2
2,4,4,4,4,4,4,4,4,4,4,4,4,4,4,4,4,4,2
2,4,4,4,4,4,4,4,4,4,4,4,4,4,4,4,4,4,2
2,4,4,4,4,4,4,4,4,4,4,4,4,4,4,4,4,4,2
2,4,4,4,4,4,4,4,4,4,4,4,4,4,4,4,4,4,2
2,4,4,4,4,4,4,4,4,4,4,4,4,4,4,4,4,4,2
2,4,4,4,4,4,4,4,4,4,4,4,4,4,4,4,4,4,2
2,4,4,4,4,4,4,4,4,4,4,4,4,4,4,4,4,4,2
2,4,4,4,4,4,4,4,4,4,4,4,4,4,4,4,4,4,2
2,4,4,4,4,4,4,4,4,4,4,4,4,4,4,4,4,4,2
2,4,4,4,4,4,4,4,4,4,4,4,4,4,4,4,4,4,2
2,4,4,4,4,4,4,4,4,4,4,4,4,4,4,4,4,4,2
2,4,4,4,4,4,4,4,4,4,4,4,4,4,4,4,4,4,2
2,4,4,4,4,4,4,4,4,4,4,4,4,4,4,4,4,4,2
2,2,2,2,2,2,2,2,2,2,2,2,2,2,2,2,2,2,2
endlayer

layer
2,2,2,2,2,2,2,2,2,2,2,2,2,2,2,2,2,2,2
2,5,0,2,0,0,2,0,0,0,0,0,2,0,0,2,0,5,2
2,0,0,2,0,0,2,0,0,0,0,0,2,0,0,2,0,0,2
2,0,0,0,0,0,0,0,0,0,0,0,0,0,0,0,0,0,2
2,2,2,0,2,2,2,0,0,0,0,0,2,2,2,0,2,2,2
2,0,0,0,2,5,0,0,0,0,0,0,0,5,2,0,0,0,2
2,0,0,0,2,0,0,0,0,0,0,0,0,0,2,0,0,0,2
2,2,2,0,2,0,0,0,0,0,0,0,0,0,2,0,2,2,2
2,0,0,0,2,0,0,0,0,0,0,0,0,0,2,0,0,0,2
2,12,0,0,2,9,9,0,0,0,0,0,9,9,2,0,0,12,2
2,0,0,0,2,8,8,0,0,0,0,0,8,8,2,0,0,0,2
2,2,2,0,2,8,8,0,0,0,0,0,8,8,2,0,2,2,2
2,0,0,0,2,8,8,8,8,8,8,8,8,8,2,0,0,0,2
2,0,0,0,2,8,8,8,8,8,8,8,8,8,2,0,0,0,2
2,2,2,0,2,2,2,2,2,2,2,2,2,2,2,0,2,2,2
2,0,0,0,0,0,0,0,0,0,0,0,0,0,0,0,0,0,2
2,0,0,2,0,0,2,0,0,2,0,0,2,0,0,2,0,0,2
2,5,0,2,0,0,2,0,0,2,0,0,2,0,0,2,0,5,2
2,2,2,2,2,2,2,2,2,2,2,2,2,2,2,2,2,2,2
endlayer

layer
2,2,2,2,2,2,2,2,2,2,2,2,2,2,2,2,2,2,2
2,0,0,2,0,0,2,0,0,0,0,0,2,0,0,2,0,0,2
2,0,0,2,0,0,2,0,0,0,0,0,2,0,0,2,0,0,2
2,0,0,0,0,0,0,0,0,0,0,0,0,0,0,0,0,0,2
2,2,2,0,2,2,2,0,0,0,0,0,2,2,2,0,2,2,2
2,0,0,0,2,0,0,0,0,0,0,0,0,0,2,0,0,0,2
2,0,0,0,2,0,0,0,0,0,0,0,0,0,2,0,0,0,2
2,2,2,0,2,0,0,0,0,0,0,0,0,0,2,0,2,2,2
2,0,0,0,2,0,0,0,0,0,0,0,0,0,2,0,0,0,2
2,0,0,0,2,0,0,0,0,0,0,0,0,0,2,0,0,0,2
2,0,0,0,2,0,0,0,0,0,0,0,0,0,2,0,0,0,2
2,2,2,0,2,9,9,0,0,0,0,0,9,9,2,0,2,2,2
2,0,0,0,2,8,8,8,8,12,8,8,8,8,2,0,0,0,2
2,0,0,0,2,8,8,8,8,8,8,8,8,8,2,0,0,0,2
2,2,2,0,2,2,2,2,2,2,2,2,2,2,2,0,2,2,2
2,0,0,0,0,0,0,0,0,0,0,0,0,0,0,0,0,0,2
2,0,0,2,0,0,2,0,0,2,0,0,2,0,0,2,0,0,2
2,0,0,2,0,0,2,0,0,2,0,0,2,0,0,2,0,0,2
2,2,2,2,2,2,2,2,2,2,2,2,2,2,2,2,2,2,2
endlayer

layer
2,2,2,2,2,2,2,2,2,2,2,2,2,2,2,2,2,2,2
2,2,2,2,2,2,2,2,2,2,2,2,2,2,2,2,2,2,2
2,2,2,2,2,2,2,2,2,2,2,2,2,2,2,2,2,2,2
2,2,2,2,2,2,2,2,2,2,2,2,2,2,2,2,2,2,2
2,2,2,2,2,2,2,2,2,2,2,2,2,2,2,2,2,2,2
2,2,2,2,2,0,0,0,0,0,0,0,0,0,2,2,2,2,2
2,2,2,2,2,0,0,0,0,0,0,0,0,0,2,2,2,2,2
2,2,2,2,2,0,0,0,0,0,0,0,0,0,2,2,2,2,2
2,2,2,2,2,0,0,0,0,0,0,0,0,0,2,2,2,2,2
2,2,2,2,2,0,0,0,0,0,0,0,0,0,2,2,2,2,2
2,2,2,2,2,0,0,0,0,0,0,0,0,0,2,2,2,2,2
2,2,2,2,2,0,0,0,0,0,0,0,0,0,2,2,2,2,2
2,2,2,2,2,0,0,9,8,8,8,9,0,0,2,2,2,2,2
2,2,2,2,2,0,0,9,8,8,8,9,0,0,2,2,2,2,2
2,2,2,2,2,2,2,2,2,2,2,2,2,2,2,2,2,2,2
2,2,2,2,2,2,2,2,2,2,2,2,2,2,2,2,2,2,2
2,2,2,2,2,2,2,2,2,2,2,2,2,2,2,2,2,2,2
2,2,2,2,2,2,2,2,2,2,2,2,2,2,2,2,2,2,2
2,2,2,2,2,2,2,2,2,2,2,2,2,2,2,2,2,2,2
endlayer

layer
0,0,0,0,0,0,0,0,0,0,0,0,0,0,0,0,0,0,0
0,0,0,0,0,0,0,0,0,0,0,0,0,0,0,0,0,0,0
0,0,1,0,0,0,1,0,0,0,0,0,1,0,0,0,1,0,0
0,0,0,0,0,0,0,0,0,0,0,0,0,0,0,0,0,0,0
0,0,0,0,2,2,2,2,2,2,2,2,2,2,2,0,0,0,0
0,0,0,0,2,0,0,0,0,0,0,0,0,0,2,0,0,0,0
0,0,1,0,2,0,0,0,0,0,0,0,0,0,2,0,1,0,0
0,0,0,0,2,0,0,0,0,0,0,0,0,0,2,0,0,0,0
0,0,0,0,2,0,0,0,0,0,0,0,0,0,2,0,0,0,0
0,0,0,0,2,0,0,0,0,0,0,0,0,0,2,0,0,0,0
0,0,0,0,2,0,0,0,0,0,0,0,0,0,2,0,0,0,0
0,0,0,0,2,0,0,0,0,0,0,0,0,0,2,0,0,0,0
0,0,1,0,2,0,0,0,0,0,0,0,0,0,2,0,1,0,0
0,0,0,0,2,0,0,0,0,0,0,0,0,0,2,0,0,0,0
0,0,0,0,2,2,2,2,0,0,0,2,2,2,2,0,0,0,0
0,0,0,0,0,0,0,0,0,0,0,0,0,0,0,0,0,0,0
0,0,1,0,0,0,1,0,0,0,0,0,1,0,0,0,1,0,0
0,0,0,0,0,0,0,0,0,0,0,0,0,0,0,0,0,0,0
0,0,0,0,0,0,0,0,0,0,0,0,0,0,0,0,0,0,0
endlayer

layer
0,0,0,0,0,0,0,0,0,0,0,0,0,0,0,0,0,0,0
0,0,0,0,0,0,0,0,0,0,0,0,0,0,0,0,0,0,0
0,0,1,0,0,0,1,0,0,0,0,0,1,0,0,0,1,0,0
0,0,0,0,0,0,0,0,0,0,0,0,0,0,0,0,0,0,0
0,0,0,0,2,2,2,2,2,2,2,2,2,2,2,0,0,0,0
0,0,0,0,2,0,0,0,0,0,0,0,0,0,2,0,0,0,0
0,0,1,0,2,0,0,0,0,0,0,0,0,0,2,0,1,0,0
0,0,0,0,2,0,0,0,0,0,0,0,0,0,2,0,0,0,0
0,0,0,0,2,0,0,0,0,0,0,0,0,0,2,0,0,0,0
0,0,0,0,2,0,0,0,0,0,0,0,0,0,2,0,0,0,0
0,0,0,0,2,0,0,0,0,0,0,0,0,0,2,0,0,0,0
0,0,0,0,2,0,0,0,0,0,0,0,0,0,2,0,0,0,0
0,0,1,0,2,0,0,0,0,0,0,0,0,0,2,0,1,0,0
0,0,0,0,2,0,0,0,0,0,0,0,0,0,2,0,0,0,0
0,0,0,0,2,2,2,2,0,0,0,2,2,2,2,0,0,0,0
0,0,0,0,0,0,0,0,0,0,0,0,0,0,0,0,0,0,0
0,0,1,0,0,0,1,0,0,0,0,0,1,0,0,0,1,0,0
0,0,0,0,0,0,0,0,0,0,0,0,0,0,0,0,0,0,0
0,0,0,0,0,0,0,0,0,0,0,0,0,0,0,0,0,0,0
endlayer

layer
0,0,0,0,0,0,0,0,0,0,0,0,0,0,0,0,0,0,0
0,0,0,0,0,0,0,0,0,0,0,0,0,0,0,0,0,0,0
0,0,1,0,0,0,1,0,0,0,0,0,1,0,0,0,1,0,0
0,0,0,0,0,0,0,0,0,0,0,0,0,0,0,0,0,0,0
0,0,0,0,2,2,2,2,2,2,2,2,2,2,2,0,0,0,0
0,0,0,0,2,0,0,0,0,0,0,0,0,0,2,0,0,0,0
0,0,1,0,2,0,0,0,0,0,0,0,0,0,2,0,1,0,0
0,0,0,0,2,0,0,0,0,0,0,0,0,0,2,0,0,0,0
0,0,0,0,2,0,0,0,0,0,0,0,0,0,2,0,0,0,0
0,0,0,0,2,0,0,0,0,0,0,0,0,0,2,0,0,0,0
0,0,0,0,2,0,0,0,0,0,0,0,0,0,2,0,0,0,0
0,0,0,0,2,0,0,0,0,0,0,0,0,0,2,0,0,0,0
0,0,1,0,2,0,0,0,0,0,0,0,0,0,2,0,1,0,0
0,0,0,0,2,0,0,0,0,0,0,0,0,0,2,0,0,0,0
0,0,0,0,2,2,2,2,0,0,0,2,2,2,2,0,0,0,0
0,0,0,0,0,0,0,0,0,0,0,0,0,0,0,0,0,0,0
0,0,1,0,0,0,1,0,0,0,0,0,1,0,0,0,1,0,0
0,0,0,0,0,0,0,0,0,0,0,0,0,0,0,0,0,0,0
0,0,0,0,0,0,0,0,0,0,0,0,0,0,0,0,0,0,0
endlayer

# THE ROOF

layer
0,0,0,0,0,0,0,0,0,0,0,0,0,0,0,0,0,0,0
0,2,2,2,2,2,2,2,2,2,2,2,2,2,2,2,2,2,0
0,2,2,2,2,2,2,2,2,2,2,2,2,2,2,2,2,2,0
0,2,2,2,2,2,2,2,2,2,2,2,2,2,2,2,2,2,0
0,2,2,2,2,2,2,2,2,2,2,2,2,2,2,2,2,2,0
0,2,2,2,2,2,2,2,2,2,2,2,2,2,2,2,2,2,0
0,2,2,2,2,2,2,2,2,2,2,2,2,2,2,2,2,2,0
0,2,2,2,2,2,2,2,2,2,2,2,2,2,2,2,2,2,0
0,2,2,2,2,2,2,2,2,2,2,2,2,2,2,2,2,2,0
0,2,2,2,2,2,2,2,2,2,2,2,2,2,2,2,2,2,0
0,2,2,2,2,2,2,2,2,2,2,2,2,2,2,2,2,2,0
0,2,2,2,2,2,2,2,2,2,2,2,2,2,2,2,2,2,0
0,2,2,2,2,2,2,2,2,2,2,2,2,2,2,2,2,2,0
0,2,2,2,2,2,2,2,2,2,2,2,2,2,2,2,2,2,0
0,2,2,2,2,2,2,2,2,2,2,2,2,2,2,2,2,2,0
0,2,2,2,2,2,2,2,2,2,2,2,2,2,2,2,2,2,0
0,2,2,2,2,2,2,2,2,2,2,2,2,2,2,2,2,2,0
0,2,2,2,2,2,2,2,2,2,2,2,2,2,2,2,2,2,0
0,0,0,0,0,0,0,0,0,0,0,0,0,0,0,0,0,0,0
endlayer

layer
0,0,0,0,0,0,0,0,0,0,0,0,0,0,0,0,0,0,0
0,2,3,3,3,3,3,3,3,3,3,3,3,3,3,3,3,2,0
0,3,10,10,10,10,10,10,10,10,10,10,10,10,10,10,10,3,0
0,3,10,10,10,10,10,10,10,10,10,10,10,10,10,10,10,3,0
0,3,10,10,10,10,10,10,10,10,10,10,10,10,10,10,10,3,0
0,3,10,10,10,10,10,10,10,10,10,10,10,10,10,10,10,3,0
0,3,10,10,10,10,10,10,10,10,10,10,10,10,10,10,10,3,0
0,3,10,10,10,10,10,10,10,10,10,10,10,10,10,10,10,3,0
0,3,10,10,10,10,10,10,10,10,10,10,10,10,10,10,10,3,0
0,3,10,10,10,10,10,10,10,10,10,10,10,10,10,10,10,3,0
0,3,10,10,10,10,10,10,10,10,10,10,10,10,10,10,10,3,0
0,3,10,10,10,10,10,10,10,10,10,10,10,10,10,10,10,3,0
0,3,10,10,10,10,10,10,10,10,10,10,10,10,10,10,10,3,0
0,3,10,10,10,10,10,10,10,10,10,10,10,10,10,10,10,3,0
0,3,10,10,10,10,10,10,10,10,10,10,10,10,10,10,10,3,0
0,3,10,10,10,10,10,10,10,10,10,10,10,10,10,10,10,3,0
0,3,10,10,10,10,10,10,10,10,10,10,10,10,10,10,10,3,0
0,2,3,3,3,3,3,3,3,3,3,3,3,3,3,3,3,2,0
0,0,0,0,0,0,0,0,0,0,0,0,0,0,0,0,0,0,0
endlayer

layer
0,0,0,0,0,0,0,0,0,0,0,0,0,0,0,0,0,0,0
0,2,3,3,2,2,2,2,3,3,3,2,2,2,2,3,3,2,0
0,3,0,0,0,0,0,0,0,0,0,0,0,0,0,0,0,3,0
0,3,0,1,1,1,1,1,1,1,1,1,1,1,1,1,0,3,0
0,2,0,1,1,1,1,1,1,1,1,1,1,1,1,1,0,2,0
0,2,0,1,1,1,1,1,1,1,1,1,1,1,1,1,0,2,0
0,2,0,1,1,1,2,2,2,2,2,2,2,1,1,1,0,2,0
0,2,0,1,1,1,2,2,2,2,2,2,2,1,1,1,0,2,0
0,3,0,1,1,1,2,2,2,2,2,2,2,1,1,1,0,3,0
0,3,0,1,1,1,2,2,2,2,2,2,2,1,1,1,0,3,0
0,3,0,1,1,1,2,2,2,2,2,2,2,1,1,1,0,3,0
0,2,0,1,1,1,2,2,2,2,2,2,2,1,1,1,0,2,0
0,2,0,1,1,1,2,2,2,2,2,2,2,1,1,1,0,2,0
0,2,0,1,1,1,1,1,1,1,1,1,1,1,1,1,0,2,0
0,2,0,1,1,1,1,1,1,1,1,1,1,1,1,1,0,2,0
0,3,0,1,1,1,1,1,1,1,1,1,1,1,1,1,0,3,0
0,3,0,0,0,0,0,0,0,0,0,0,0,0,0,0,0,3,0
0,2,3,3,2,2,2,2,3,3,3,2,2,2,2,3,3,2,0
0,0,0,0,0,0,0,0,0,0,0,0,0,0,0,0,0,0,0
endlayer

layer
0,0,0,0,0,0,0,0,0,0,0,0,0,0,0,0,0,0,0
0,2,3,2,2,0,0,2,2,3,2,2,0,0,2,2,3,2,0
0,3,0,0,0,0,0,0,0,0,0,0,0,0,0,0,0,3,0
0,2,0,0,0,0,0,0,0,0,0,0,0,0,0,0,0,2,0
0,2,0,0,1,1,1,1,1,1,1,1,1,1,1,0,0,2,0
0,0,0,0,1,1,1,1,1,1,1,1,1,1,1,0,0,0,0
0,0,0,0,1,1,2,2,2,2,2,2,2,1,1,0,0,0,0
0,2,0,0,1,1,2,2,2,2,2,2,2,1,1,0,0,2,0
0,2,0,0,1,1,2,2,2,2,2,2,2,1,1,0,0,2,0
0,3,0,0,1,1,2,2,2,2,2,2,2,1,1,0,0,3,0
0,2,0,0,1,1,2,2,2,2,2,2,2,1,1,0,0,2,0
0,2,0,0,1,1,2,2,2,2,2,2,2,1,1,0,0,2,0
0,0,0,0,1,1,2,2,2,2,2,2,2,1,1,0,0,0,0
0,0,0,0,1,1,1,1,1,1,1,1,1,1,1,0,0,0,0
0,2,0,0,1,1,1,1,1,1,1,1,1,1,1,0,0,2,0
0,2,0,0,0,0,0,0,0,0,0,0,0,0,0,0,0,2,0
0,3,0,0,0,0,0,0,0,0,0,0,0,0,0,0,0,3,0
0,2,3,2,2,0,0,2,2,3,2,2,0,0,2,2,3,2,0
0,0,0,0,0,0,0,0,0,0,0,0,0,0,0,0,0,0,0
endlayer

layer
0,0,0,0,0,0,0,0,0,0,0,0,0,0,0,0,0,0,0
0,2,2,2,0,0,0,0,2,2,2,0,0,0,0,2,2,2,0
0,2,0,0,0,0,0,0,0,0,0,0,0,0,0,0,0,2,0
0,2,0,0,0,0,0,0,0,0,0,0,0,0,0,0,0,2,0
0,0,0,0,0,0,0,0,0,0,0,0,0,0,0,0,0,0,0
0,0,0,0,0,1,1,1,1,1,1,1,1,1,0,0,0,0,0
0,0,0,0,0,1,2,2,2,2,2,2,2,1,0,0,0,0,0
0,0,0,0,0,1,2,2,2,2,2,2,2,1,0,0,0,0,0
0,2,0,0,0,1,2,2,2,2,2,2,2,1,0,0,0,2,0
0,2,0,0,0,1,2,2,2,2,2,2,2,1,0,0,0,2,0
0,2,0,0,0,1,2,2,2,2,2,2,2,1,0,0,0,2,0
0,0,0,0,0,1,2,2,2,2,2,2,2,1,0,0,0,0,0
0,0,0,0,0,1,2,2,2,2,2,2,2,1,0,0,0,0,0
0,0,0,0,0,1,1,1,1,1,1,1,1,1,0,0,0,0,0
0,0,0,0,0,0,0,0,0,0,0,0,0,0,0,0,0,0,0
0,2,0,0,0,0,0,0,0,0,0,0,0,0,0,0,0,2,0
0,2,0,0,0,0,0,0,0,0,0,0,0,0,0,0,0,2,0
0,2,2,2,0,0,0,0,2,2,2,0,0,0,0,2,2,2,0
0,0,0,0,0,0,0,0,0,0,0,0,0,0,0,0,0,0,0
endlayer

layer
0,0,0,0,0,0,0,0,0,0,0,0,0,0,0,0,0,0,0
0,2,2,0,0,0,0,0,0,2,0,0,0,0,0,0,2,2,0
0,2,0,0,0,0,0,0,0,0,0,0,0,0,0,0,0,2,0
0,0,0,0,0,0,0,0,0,0,0,0,0,0,0,0,0,0,0
0,0,0,0,0,0,0,0,0,0,0,0,0,0,0,0,0,0,0
0,0,0,0,0,0,0,0,0,0,0,0,0,0,0,0,0,0,0
0,0,0,0,0,0,1,1,1,1,1,1,1,0,0,0,0,0,0
0,0,0,0,0,0,1,2,2,2,2,2,1,0,0,0,0,0,0
0,0,0,0,0,0,1,2,2,2,2,2,1,0,0,0,0,0,0
0,0,0,0,0,0,1,2,2,2,2,2,1,0,0,0,0,2,0
0,2,0,0,0,0,1,2,2,2,2,2,1,0,0,0,0,0,0
0,0,0,0,0,0,1,2,2,2,2,2,1,0,0,0,0,0,0
0,0,0,0,0,0,1,1,1,1,1,1,1,0,0,0,0,0,0
0,0,0,0,0,0,0,0,0,0,0,0,0,0,0,0,0,0,0
0,0,0,0,0,0,0,0,0,0,0,0,0,0,0,0,0,0,0
0,0,0,0,0,0,0,0,0,0,0,0,0,0,0,0,0,0,0
0,2,0,0,0,0,0,0,0,0,0,0,0,0,0,0,0,2,0
0,2,2,0,0,0,0,0,0,2,0,0,0,0,0,0,2,2,0
0,0,0,0,0,0,0,0,0,0,0,0,0,0,0,0,0,0,0
endlayer

layer
0,0,0,0,0,0,0,0,0,0,0,0,0,0,0,0,0,0,0
0,2,0,0,0,0,0,0,0,0,0,0,0,0,0,0,0,2,0
0,0,0,0,0,0,0,0,0,0,0,0,0,0,0,0,0,0,0
0,0,0,0,0,0,0,0,0,0,0,0,0,0,0,0,0,0,0
0,0,0,0,0,0,0,0,0,0,0,0,0,0,0,0,0,0,0
0,0,0,0,0,0,0,0,0,0,0,0,0,0,0,0,0,0,0
0,0,0,0,0,0,0,0,0,0,0,0,0,0,0,0,0,0,0
0,0,0,0,0,0,0,1,1,1,1,1,0,0,0,0,0,0,0
0,0,0,0,0,0,0,1,2,2,2,1,0,0,0,0,0,0,0
0,0,0,0,0,0,0,1,2,2,2,1,0,0,0,0,0,0,0
0,0,0,0,0,0,0,1,2,2,2,1,0,0,0,0,0,0,0
0,0,0,0,0,0,0,1,1,1,1,1,0,0,0,0,0,0,0
0,0,0,0,0,0,0,0,0,0,0,0,0,0,0,0,0,0,0
0,0,0,0,0,0,0,0,0,0,0,0,0,0,0,0,0,0,0
0,0,0,0,0,0,0,0,0,0,0,0,0,0,0,0,0,0,0
0,0,0,0,0,0,0,0,0,0,0,0,0,0,0,0,0,0,0
0,0,0,0,0,0,0,0,0,0,0,0,0,0,0,0,0,0,0
0,2,0,0,0,0,0,0,0,0,0,0,0,0,0,0,0,2,0
0,0,0,0,0,0,0,0,0,0,0,0,0,0,0,0,0,0,0
endlayer

layer
0,0,0,0,0,0,0,0,0,0,0,0,0,0,0,0,0,0,0
0,0,0,0,0,0,0,0,0,0,0,0,0,0,0,0,0,0,0
0,0,0,0,0,0,0,0,0,0,0,0,0,0,0,0,0,0,0
0,0,0,0,0,0,0,0,0,0,0,0,0,0,0,0,0,0,0
0,0,0,0,0,0,0,0,0,0,0,0,0,0,0,0,0,0,0
0,0,0,0,0,0,0,0,0,0,0,0,0,0,0,0,0,0,0
0,0,0,0,0,0,0,0,0,0,0,0,0,0,0,0,0,0,0
0,0,0,0,0,0,0,0,0,0,0,0,0,0,0,0,0,0,0
0,0,0,0,0,0,0,0,1,1,1,0,0,0,0,0,0,0,0
0,0,0,0,0,0,0,0,1,1,1,0,0,0,0,0,0,0,0
0,0,0,0,0,0,0,0,1,1,1,0,0,0,0,0,0,0,0
0,0,0,0,0,0,0,0,0,0,0,0,0,0,0,0,0,0,0
0,0,0,0,0,0,0,0,0,0,0,0,0,0,0,0,0,0,0
0,0,0,0,0,0,0,0,0,0,0,0,0,0,0,0,0,0,0
0,0,0,0,0,0,0,0,0,0,0,0,0,0,0,0,0,0,0
0,0,0,0,0,0,0,0,0,0,0,0,0,0,0,0,0,0,0
0,0,0,0,0,0,0,0,0,0,0,0,0,0,0,0,0,0,0
0,0,0,0,0,0,0,0,0,0,0,0,0,0,0,0,0,0,0
0,0,0,0,0,0,0,0,0,0,0,0,0,0,0,0,0,0,0
endlayer
