#BASICS

weight=7
embed_into_distance=0
acceptable_target_blocks=1,2,3,9,12,13,49,79,110
dimensions=26,19,19
allowable_overhang=100
max_cut_in=5
cut_in_buffer=1
max_leveling=5
leveling_buffer=1
preserve_water=0
preserve_lava=0
preserve_plants=0


#RULES LIST - SETS BLOCK NUMBERS

rule1=0,100,49
rule2=0,100,24
rule3=0,100,49
rule4=0,100,5
rule5=0,100,85
rule6=0,100,24
rule7=0,100,47
rule8=0,100,5
rule9=0,100,44-2
rule10=0,100,24
rule11=0,100,25
rule12=0,100,302

#MY LIST OF BLOCKS

#     0 = AIR
#     1 = Obsidian
#     2 = Sandstone
#     3 = Obsidian
#     4 = Planks
#     5 = Fencepost
#     6 = Water
#     7 = Bookshelf
#     8 = Planks
#     9 = Plank-Slab
#     10 = Stationary Water
#     11 = Note Block
#     12 = Skelly Spawner

#     300 = Leave existing world block alone
#     301 = Mob Spawner (Zombie)
#     302 = Mob Spawner (Skeleton) 
#     303 = Mob Spawner (Spider)
#     304 = Mob Spawner (Creeper)
#     305 = Mob Spawner (Zombie, Skeleton, Creeper)
#     306 = Mob Spawner (Easy, zombies and skeletons)
#     307 = Mob Spawner (Medium, zombies, skeletons, and spiders)
#     308 = Mob Spawner (Hard, all mobs)
#     309 = Easy Chest (For Easy rewards)
#     310 = Medium Chest (For Medium rewards)
#     311 = Hard Chest (For Hard rewards)


# LAYERS
# Each layer is a comma-delimited list of rules, one for each block.  There
# must be as many layers as the height, and each layer must have "layer" before
# the rules and end with "endlayer".  There are as many rows as the length, and
# as many rules as the width.  If you want the block blanked out use 0, which
# represents the Air-block rule.



#Empty Air (REPEATed)

layer
0,0,0,0,0,0,0,0,0,0,0,0,0,0,0,0,0,0,0
0,0,0,0,0,0,0,0,0,0,0,0,0,0,0,0,0,0,0
0,0,0,0,0,0,0,0,0,0,0,0,0,0,0,0,0,0,0
0,0,0,0,0,0,0,0,0,0,0,0,0,0,0,0,0,0,0
0,0,0,0,0,0,0,0,0,0,0,0,0,0,0,0,0,0,0
0,0,0,0,0,0,0,0,0,0,0,0,0,0,0,0,0,0,0
0,0,0,0,0,0,0,0,0,0,0,0,0,0,0,0,0,0,0
0,0,0,0,0,0,0,0,0,0,0,0,0,0,0,0,0,0,0
0,0,0,0,0,0,0,0,0,0,0,0,0,0,0,0,0,0,0
0,0,0,0,0,0,0,0,0,0,0,0,0,0,0,0,0,0,0
0,0,0,0,0,0,0,0,0,0,0,0,0,0,0,0,0,0,0
0,0,0,0,0,0,0,0,0,0,0,0,0,0,0,0,0,0,0
0,0,0,0,0,0,0,0,0,0,0,0,0,0,0,0,0,0,0
0,0,0,0,0,0,0,0,0,0,0,0,0,0,0,0,0,0,0
0,0,0,0,0,0,0,0,0,0,0,0,0,0,0,0,0,0,0
0,0,0,0,0,0,0,0,0,0,0,0,0,0,0,0,0,0,0
0,0,0,0,0,0,0,0,0,0,0,0,0,0,0,0,0,0,0
0,0,0,0,0,0,0,0,0,0,0,0,0,0,0,0,0,0,0
0,0,0,0,0,0,0,0,0,0,0,0,0,0,0,0,0,0,0
endlayer

layer
0,0,0,0,0,0,0,0,0,0,0,0,0,0,0,0,0,0,0
0,0,0,0,0,0,0,0,0,0,0,0,0,0,0,0,0,0,0
0,0,0,0,0,0,0,0,0,0,0,0,0,0,0,0,0,0,0
0,0,0,0,0,0,0,0,0,0,0,0,0,0,0,0,0,0,0
0,0,0,0,0,0,0,0,0,0,0,0,0,0,0,0,0,0,0
0,0,0,0,0,0,0,0,0,0,0,0,0,0,0,0,0,0,0
0,0,0,0,0,0,0,0,0,0,0,0,0,0,0,0,0,0,0
0,0,0,0,0,0,0,0,0,0,0,0,0,0,0,0,0,0,0
0,0,0,0,0,0,0,0,0,0,0,0,0,0,0,0,0,0,0
0,0,0,0,0,0,0,0,0,0,0,0,0,0,0,0,0,0,0
0,0,0,0,0,0,0,0,0,0,0,0,0,0,0,0,0,0,0
0,0,0,0,0,0,0,0,0,0,0,0,0,0,0,0,0,0,0
0,0,0,0,0,0,0,0,0,0,0,0,0,0,0,0,0,0,0
0,0,0,0,0,0,0,0,0,0,0,0,0,0,0,0,0,0,0
0,0,0,0,0,0,0,0,0,0,0,0,0,0,0,0,0,0,0
0,0,0,0,0,0,0,0,0,0,0,0,0,0,0,0,0,0,0
0,0,0,0,0,0,0,0,0,0,0,0,0,0,0,0,0,0,0
0,0,0,0,0,0,0,0,0,0,0,0,0,0,0,0,0,0,0
0,0,0,0,0,0,0,0,0,0,0,0,0,0,0,0,0,0,0
endlayer

layer
0,0,0,0,0,0,0,0,0,0,0,0,0,0,0,0,0,0,0
0,0,0,0,0,0,0,0,0,0,0,0,0,0,0,0,0,0,0
0,0,0,0,0,0,0,0,0,0,0,0,0,0,0,0,0,0,0
0,0,0,0,0,0,0,0,0,0,0,0,0,0,0,0,0,0,0
0,0,0,0,0,0,0,0,0,0,0,0,0,0,0,0,0,0,0
0,0,0,0,0,0,0,0,0,0,0,0,0,0,0,0,0,0,0
0,0,0,0,0,0,0,0,0,0,0,0,0,0,0,0,0,0,0
0,0,0,0,0,0,0,0,0,0,0,0,0,0,0,0,0,0,0
0,0,0,0,0,0,0,0,0,0,0,0,0,0,0,0,0,0,0
0,0,0,0,0,0,0,0,0,0,0,0,0,0,0,0,0,0,0
0,0,0,0,0,0,0,0,0,0,0,0,0,0,0,0,0,0,0
0,0,0,0,0,0,0,0,0,0,0,0,0,0,0,0,0,0,0
0,0,0,0,0,0,0,0,0,0,0,0,0,0,0,0,0,0,0
0,0,0,0,0,0,0,0,0,0,0,0,0,0,0,0,0,0,0
0,0,0,0,0,0,0,0,0,0,0,0,0,0,0,0,0,0,0
0,0,0,0,0,0,0,0,0,0,0,0,0,0,0,0,0,0,0
0,0,0,0,0,0,0,0,0,0,0,0,0,0,0,0,0,0,0
0,0,0,0,0,0,0,0,0,0,0,0,0,0,0,0,0,0,0
0,0,0,0,0,0,0,0,0,0,0,0,0,0,0,0,0,0,0
endlayer

layer
0,0,0,0,0,0,0,0,0,0,0,0,0,0,0,0,0,0,0
0,0,0,0,0,0,0,0,0,0,0,0,0,0,0,0,0,0,0
0,0,0,0,0,0,0,0,0,0,0,0,0,0,0,0,0,0,0
0,0,0,0,0,0,0,0,0,0,0,0,0,0,0,0,0,0,0
0,0,0,0,0,0,0,0,0,0,0,0,0,0,0,0,0,0,0
0,0,0,0,0,0,0,0,0,0,0,0,0,0,0,0,0,0,0
0,0,0,0,0,0,0,0,0,0,0,0,0,0,0,0,0,0,0
0,0,0,0,0,0,0,0,0,0,0,0,0,0,0,0,0,0,0
0,0,0,0,0,0,0,0,0,0,0,0,0,0,0,0,0,0,0
0,0,0,0,0,0,0,0,0,0,0,0,0,0,0,0,0,0,0
0,0,0,0,0,0,0,0,0,0,0,0,0,0,0,0,0,0,0
0,0,0,0,0,0,0,0,0,0,0,0,0,0,0,0,0,0,0
0,0,0,0,0,0,0,0,0,0,0,0,0,0,0,0,0,0,0
0,0,0,0,0,0,0,0,0,0,0,0,0,0,0,0,0,0,0
0,0,0,0,0,0,0,0,0,0,0,0,0,0,0,0,0,0,0
0,0,0,0,0,0,0,0,0,0,0,0,0,0,0,0,0,0,0
0,0,0,0,0,0,0,0,0,0,0,0,0,0,0,0,0,0,0
0,0,0,0,0,0,0,0,0,0,0,0,0,0,0,0,0,0,0
0,0,0,0,0,0,0,0,0,0,0,0,0,0,0,0,0,0,0
endlayer

layer
0,0,0,0,0,0,0,0,0,0,0,0,0,0,0,0,0,0,0
0,0,0,0,0,0,0,0,0,0,0,0,0,0,0,0,0,0,0
0,0,0,0,0,0,0,0,0,0,0,0,0,0,0,0,0,0,0
0,0,0,0,0,0,0,0,0,0,0,0,0,0,0,0,0,0,0
0,0,0,0,0,0,0,0,0,0,0,0,0,0,0,0,0,0,0
0,0,0,0,0,0,0,0,0,0,0,0,0,0,0,0,0,0,0
0,0,0,0,0,0,0,0,0,0,0,0,0,0,0,0,0,0,0
0,0,0,0,0,0,0,0,0,0,0,0,0,0,0,0,0,0,0
0,0,0,0,0,0,0,0,0,0,0,0,0,0,0,0,0,0,0
0,0,0,0,0,0,0,0,0,0,0,0,0,0,0,0,0,0,0
0,0,0,0,0,0,0,0,0,0,0,0,0,0,0,0,0,0,0
0,0,0,0,0,0,0,0,0,0,0,0,0,0,0,0,0,0,0
0,0,0,0,0,0,0,0,0,0,0,0,0,0,0,0,0,0,0
0,0,0,0,0,0,0,0,0,0,0,0,0,0,0,0,0,0,0
0,0,0,0,0,0,0,0,0,0,0,0,0,0,0,0,0,0,0
0,0,0,0,0,0,0,0,0,0,0,0,0,0,0,0,0,0,0
0,0,0,0,0,0,0,0,0,0,0,0,0,0,0,0,0,0,0
0,0,0,0,0,0,0,0,0,0,0,0,0,0,0,0,0,0,0
0,0,0,0,0,0,0,0,0,0,0,0,0,0,0,0,0,0,0
endlayer

layer
0,0,0,0,0,0,0,0,0,0,0,0,0,0,0,0,0,0,0
0,0,0,0,0,0,0,0,0,0,0,0,0,0,0,0,0,0,0
0,0,0,0,0,0,0,0,0,0,0,0,0,0,0,0,0,0,0
0,0,0,0,0,0,0,0,0,0,0,0,0,0,0,0,0,0,0
0,0,0,0,0,0,0,0,0,0,0,0,0,0,0,0,0,0,0
0,0,0,0,0,0,0,0,0,0,0,0,0,0,0,0,0,0,0
0,0,0,0,0,0,0,0,0,0,0,0,0,0,0,0,0,0,0
0,0,0,0,0,0,0,0,0,0,0,0,0,0,0,0,0,0,0
0,0,0,0,0,0,0,0,0,0,0,0,0,0,0,0,0,0,0
0,0,0,0,0,0,0,0,0,0,0,0,0,0,0,0,0,0,0
0,0,0,0,0,0,0,0,0,0,0,0,0,0,0,0,0,0,0
0,0,0,0,0,0,0,0,0,0,0,0,0,0,0,0,0,0,0
0,0,0,0,0,0,0,0,0,0,0,0,0,0,0,0,0,0,0
0,0,0,0,0,0,0,0,0,0,0,0,0,0,0,0,0,0,0
0,0,0,0,0,0,0,0,0,0,0,0,0,0,0,0,0,0,0
0,0,0,0,0,0,0,0,0,0,0,0,0,0,0,0,0,0,0
0,0,0,0,0,0,0,0,0,0,0,0,0,0,0,0,0,0,0
0,0,0,0,0,0,0,0,0,0,0,0,0,0,0,0,0,0,0
0,0,0,0,0,0,0,0,0,0,0,0,0,0,0,0,0,0,0
endlayer

#CAPSTONE

layer
0,0,0,0,0,0,0,0,0,0,0,0,0,0,0,0,0,0,0
0,0,0,0,0,0,0,0,0,0,0,0,0,0,0,0,0,0,0
0,0,0,0,0,0,0,0,0,0,0,0,0,0,0,0,0,0,0
0,0,0,0,0,0,0,0,0,0,0,0,0,0,0,0,0,0,0
0,0,0,0,0,0,0,0,0,0,0,0,0,0,0,0,0,0,0
0,0,0,0,0,0,0,0,0,0,0,0,0,0,0,0,0,0,0
0,0,0,0,0,0,0,0,0,0,0,0,0,0,0,0,0,0,0
0,0,0,0,0,0,0,0,0,0,0,0,0,0,0,0,0,0,0
0,0,0,0,0,0,0,0,1,1,1,0,0,0,0,0,0,0,0
0,0,0,0,0,0,0,0,1,1,1,0,0,0,0,0,0,0,0
0,0,0,0,0,0,0,0,1,1,1,0,0,0,0,0,0,0,0
0,0,0,0,0,0,0,0,0,0,0,0,0,0,0,0,0,0,0
0,0,0,0,0,0,0,0,0,0,0,0,0,0,0,0,0,0,0
0,0,0,0,0,0,0,0,0,0,0,0,0,0,0,0,0,0,0
0,0,0,0,0,0,0,0,0,0,0,0,0,0,0,0,0,0,0
0,0,0,0,0,0,0,0,0,0,0,0,0,0,0,0,0,0,0
0,0,0,0,0,0,0,0,0,0,0,0,0,0,0,0,0,0,0
0,0,0,0,0,0,0,0,0,0,0,0,0,0,0,0,0,0,0
0,0,0,0,0,0,0,0,0,0,0,0,0,0,0,0,0,0,0
endlayer

layer
0,0,0,0,0,0,0,0,0,0,0,0,0,0,0,0,0,0,0
0,2,0,0,0,0,0,0,0,0,0,0,0,0,0,0,0,2,0
0,0,0,0,0,0,0,0,0,0,0,0,0,0,0,0,0,0,0
0,0,0,0,0,0,0,0,0,0,0,0,0,0,0,0,0,0,0
0,0,0,0,0,0,0,0,0,0,0,0,0,0,0,0,0,0,0
0,0,0,0,0,0,0,0,0,0,0,0,0,0,0,0,0,0,0
0,0,0,0,0,0,0,0,0,0,0,0,0,0,0,0,0,0,0
0,0,0,0,0,0,0,1,1,1,1,1,0,0,0,0,0,0,0
0,0,0,0,0,0,0,1,2,2,2,1,0,0,0,0,0,0,0
0,0,0,0,0,0,0,1,2,2,2,1,0,0,0,0,0,0,0
0,0,0,0,0,0,0,1,2,2,2,1,0,0,0,0,0,0,0
0,0,0,0,0,0,0,1,1,1,1,1,0,0,0,0,0,0,0
0,0,0,0,0,0,0,0,0,0,0,0,0,0,0,0,0,0,0
0,0,0,0,0,0,0,0,0,0,0,0,0,0,0,0,0,0,0
0,0,0,0,0,0,0,0,0,0,0,0,0,0,0,0,0,0,0
0,0,0,0,0,0,0,0,0,0,0,0,0,0,0,0,0,0,0
0,0,0,0,0,0,0,0,0,0,0,0,0,0,0,0,0,0,0
0,2,0,0,0,0,0,0,0,0,0,0,0,0,0,0,0,2,0
0,0,0,0,0,0,0,0,0,0,0,0,0,0,0,0,0,0,0
endlayer

layer
0,0,0,0,0,0,0,0,0,0,0,0,0,0,0,0,0,0,0
0,2,2,0,0,0,0,0,0,2,0,0,0,0,0,0,2,2,0
0,2,0,0,0,0,0,0,0,0,0,0,0,0,0,0,0,2,0
0,0,0,0,0,0,0,0,0,0,0,0,0,0,0,0,0,0,0
0,0,0,0,0,0,0,0,0,0,0,0,0,0,0,0,0,0,0
0,0,0,0,0,0,0,0,0,0,0,0,0,0,0,0,0,0,0
0,0,0,0,0,0,1,1,1,1,1,1,1,0,0,0,0,0,0
0,0,0,0,0,0,1,2,2,2,2,2,1,0,0,0,0,0,0
0,0,0,0,0,0,1,2,2,2,2,2,1,0,0,0,0,0,0
0,0,0,0,0,0,1,2,2,2,2,2,1,0,0,0,0,2,0
0,2,0,0,0,0,1,2,2,2,2,2,1,0,0,0,0,0,0
0,0,0,0,0,0,1,2,2,2,2,2,1,0,0,0,0,0,0
0,0,0,0,0,0,1,1,1,1,1,1,1,0,0,0,0,0,0
0,0,0,0,0,0,0,0,0,0,0,0,0,0,0,0,0,0,0
0,0,0,0,0,0,0,0,0,0,0,0,0,0,0,0,0,0,0
0,0,0,0,0,0,0,0,0,0,0,0,0,0,0,0,0,0,0
0,2,0,0,0,0,0,0,0,0,0,0,0,0,0,0,0,2,0
0,2,2,0,0,0,0,0,0,2,0,0,0,0,0,0,2,2,0
0,0,0,0,0,0,0,0,0,0,0,0,0,0,0,0,0,0,0
endlayer

layer
0,0,0,0,0,0,0,0,0,0,0,0,0,0,0,0,0,0,0
0,2,2,2,0,0,0,0,2,2,2,0,0,0,0,2,2,2,0
0,2,0,0,0,0,0,0,0,0,0,0,0,0,0,0,0,2,0
0,2,0,0,0,0,0,0,0,0,0,0,0,0,0,0,0,2,0
0,0,0,0,0,0,0,0,0,0,0,0,0,0,0,0,0,0,0
0,0,0,0,0,1,1,1,1,1,1,1,1,1,0,0,0,0,0
0,0,0,0,0,1,2,2,2,2,2,2,2,1,0,0,0,0,0
0,0,0,0,0,1,2,2,2,2,2,2,2,1,0,0,0,0,0
0,2,0,0,0,1,2,2,2,2,2,2,2,1,0,0,0,2,0
0,2,0,0,0,1,2,2,2,2,2,2,2,1,0,0,0,2,0
0,2,0,0,0,1,2,2,2,2,2,2,2,1,0,0,0,2,0
0,0,0,0,0,1,2,2,2,2,2,2,2,1,0,0,0,0,0
0,0,0,0,0,1,2,2,2,2,2,2,2,1,0,0,0,0,0
0,0,0,0,0,1,1,1,1,1,1,1,1,1,0,0,0,0,0
0,0,0,0,0,0,0,0,0,0,0,0,0,0,0,0,0,0,0
0,2,0,0,0,0,0,0,0,0,0,0,0,0,0,0,0,2,0
0,2,0,0,0,0,0,0,0,0,0,0,0,0,0,0,0,2,0
0,2,2,2,0,0,0,0,2,2,2,0,0,0,0,2,2,2,0
0,0,0,0,0,0,0,0,0,0,0,0,0,0,0,0,0,0,0
endlayer

layer
0,0,0,0,0,0,0,0,0,0,0,0,0,0,0,0,0,0,0
0,2,3,2,2,0,0,2,2,3,2,2,0,0,2,2,3,2,0
0,3,6,6,0,0,0,0,6,6,6,0,0,0,0,6,6,3,0
0,2,0,0,0,0,0,0,0,0,0,0,0,0,0,0,6,2,0
0,2,0,0,1,1,1,1,1,1,1,1,1,1,1,0,0,2,0
0,0,0,0,1,1,1,1,1,1,1,1,1,1,1,0,0,0,0
0,0,0,0,1,1,2,2,2,2,2,2,2,1,1,0,0,0,0
0,2,0,0,1,1,2,2,2,2,2,2,2,1,1,0,0,2,0
0,2,6,0,1,1,2,2,2,2,2,2,2,1,1,0,6,2,0
0,3,6,0,1,1,2,2,2,2,2,2,2,1,1,0,6,3,0
0,2,6,0,1,1,2,2,2,2,2,2,2,1,1,0,6,2,0
0,2,0,0,1,1,2,2,2,2,2,2,2,1,1,0,0,2,0
0,0,0,0,1,1,2,2,2,2,2,2,2,1,1,0,0,0,0
0,0,0,0,1,1,1,1,1,1,1,1,1,1,1,0,0,0,0
0,2,0,0,1,1,1,1,1,1,1,1,1,1,1,0,0,2,0
0,2,6,0,0,0,0,0,0,0,0,0,0,0,0,0,6,2,0
0,3,6,6,0,0,0,0,6,6,6,0,0,0,0,6,6,3,0
0,2,3,2,2,0,0,2,2,3,2,2,0,0,2,2,3,2,0
0,0,0,0,0,0,0,0,0,0,0,0,0,0,0,0,0,0,0
endlayer

layer
0,0,0,0,0,0,0,0,0,0,0,0,0,0,0,0,0,0,0
0,2,3,3,2,2,2,2,3,3,3,2,2,2,2,3,3,2,0
0,3,6,6,2,2,2,2,6,6,6,2,2,2,2,6,6,3,0
0,3,6,1,1,1,1,1,1,1,1,1,1,1,1,1,6,3,0
0,2,2,1,1,1,1,1,1,1,1,1,1,1,1,1,2,2,0
0,2,2,1,1,1,1,1,1,1,1,1,1,1,1,1,2,2,0
0,2,2,1,1,1,2,2,2,2,2,2,2,1,1,1,2,2,0
0,2,2,1,1,1,2,2,2,2,2,2,2,1,1,1,2,2,0
0,3,6,1,1,1,2,2,2,2,2,2,2,1,1,1,6,3,0
0,3,6,1,1,1,2,2,2,2,2,2,2,1,1,1,6,3,0
0,3,6,1,1,1,2,2,2,2,2,2,2,1,1,1,6,3,0
0,2,2,1,1,1,2,2,2,2,2,2,2,1,1,1,2,2,0
0,2,2,1,1,1,2,2,2,2,2,2,2,1,1,1,2,2,0
0,2,2,1,1,1,1,1,1,1,1,1,1,1,1,1,2,2,0
0,2,2,1,1,1,1,1,1,1,1,1,1,1,1,1,2,2,0
0,3,6,1,1,1,1,1,1,1,1,1,1,1,1,1,6,3,0
0,3,6,6,2,2,2,2,6,6,6,2,2,2,2,6,6,3,0
0,2,3,3,2,2,2,2,3,3,3,2,2,2,2,3,3,2,0
0,0,0,0,0,0,0,0,0,0,0,0,0,0,0,0,0,0,0
endlayer

layer
0,0,0,0,0,0,0,0,0,0,0,0,0,0,0,0,0,0,0
0,2,3,3,3,3,3,3,3,3,3,3,3,3,3,3,3,2,0
0,3,10,10,10,10,10,10,10,10,10,10,10,10,10,10,10,3,0
0,3,10,10,10,10,10,10,10,10,10,10,10,10,10,10,10,3,0
0,3,10,10,10,10,10,10,10,10,10,10,10,10,10,10,10,3,0
0,3,10,10,10,10,10,10,10,10,10,10,10,10,10,10,10,3,0
0,3,10,10,10,10,10,10,10,10,10,10,10,10,10,10,10,3,0
0,3,10,10,10,10,10,10,10,10,10,10,10,10,10,10,10,3,0
0,3,10,10,10,10,10,10,10,10,10,10,10,10,10,10,10,3,0
0,3,10,10,10,10,10,10,10,10,10,10,10,10,10,10,10,3,0
0,3,10,10,10,10,10,10,10,10,10,10,10,10,10,10,10,3,0
0,3,10,10,10,10,10,10,10,10,10,10,10,10,10,10,10,3,0
0,3,10,10,10,10,10,10,10,10,10,10,10,10,10,10,10,3,0
0,3,10,10,10,10,10,10,10,10,10,10,10,10,10,10,10,3,0
0,3,10,10,10,10,10,10,10,10,10,10,10,10,10,10,10,3,0
0,3,10,10,10,10,10,10,10,10,10,10,10,10,10,10,10,3,0
0,3,10,10,10,10,10,10,10,10,10,10,10,10,10,10,10,3,0
0,2,3,3,3,3,3,3,3,3,3,3,3,3,3,3,3,2,0
0,0,0,0,0,0,0,0,0,0,0,0,0,0,0,0,0,0,0
endlayer

layer
0,0,0,0,0,0,0,0,0,0,0,0,0,0,0,0,0,0,0
0,2,2,2,2,2,2,2,2,2,2,2,2,2,2,2,2,2,0
0,2,2,2,2,2,2,2,2,2,2,2,2,2,2,2,2,2,0
0,2,2,2,2,2,2,2,2,2,2,2,2,2,2,2,2,2,0
0,2,2,2,2,2,2,2,2,2,2,2,2,2,2,2,2,2,0
0,2,2,2,2,2,2,2,2,2,2,2,2,2,2,2,2,2,0
0,2,2,2,2,2,2,2,2,2,2,2,2,2,2,2,2,2,0
0,2,2,2,2,2,2,2,2,2,2,2,2,2,2,2,2,2,0
0,2,2,2,2,2,2,2,2,2,2,2,2,2,2,2,2,2,0
0,2,2,2,2,2,2,2,2,2,2,2,2,2,2,2,2,2,0
0,2,2,2,2,2,2,2,2,2,2,2,2,2,2,2,2,2,0
0,2,2,2,2,2,2,2,2,2,2,2,2,2,2,2,2,2,0
0,2,2,2,2,2,2,2,2,2,2,2,2,2,2,2,2,2,0
0,2,2,2,2,2,2,2,2,2,2,2,2,2,2,2,2,2,0
0,2,2,2,2,2,2,2,2,2,2,2,2,2,2,2,2,2,0
0,2,2,2,2,2,2,2,2,2,2,2,2,2,2,2,2,2,0
0,2,2,2,2,2,2,2,2,2,2,2,2,2,2,2,2,2,0
0,2,2,2,2,2,2,2,2,2,2,2,2,2,2,2,2,2,0
0,0,0,0,0,0,0,0,0,0,0,0,0,0,0,0,0,0,0
endlayer

#THE TEMPLE PROPER

layer
0,0,0,0,0,0,0,0,0,0,0,0,0,0,0,0,0,0,0
0,5,5,5,5,5,5,5,5,5,5,5,5,5,5,5,5,5,0
0,5,0,0,0,0,0,0,0,0,0,0,0,0,0,0,0,5,0
0,5,0,0,0,0,0,0,0,0,0,0,0,0,0,0,0,5,0
0,5,0,0,2,2,2,2,2,2,2,2,2,2,2,0,0,5,0
0,5,0,0,2,7,7,7,7,7,2,7,7,7,2,0,0,5,0
0,5,0,0,2,7,0,0,0,7,2,0,0,0,2,0,0,5,0
0,5,0,0,2,7,0,12,0,0,0,0,0,0,2,0,0,5,0
0,5,0,0,2,7,0,0,0,7,2,0,0,0,2,0,0,5,0
0,5,0,0,2,7,7,7,7,7,2,2,0,2,2,0,0,5,0
0,5,0,0,2,2,2,2,2,2,0,0,0,7,2,0,0,5,0
0,5,0,0,2,2,2,2,2,2,0,0,0,7,2,0,0,5,0
0,5,0,0,2,0,0,0,0,0,0,0,0,7,2,0,0,5,0
0,5,0,0,2,0,0,0,0,2,0,0,0,7,2,0,0,5,0
0,5,0,0,2,3,0,0,3,2,2,2,2,2,2,0,0,5,0
0,5,0,0,0,0,0,0,0,0,0,0,0,0,0,0,0,5,0
0,5,0,0,0,0,0,0,0,0,0,0,0,0,0,0,0,5,0
0,5,5,5,5,5,5,5,5,5,5,5,5,5,5,5,5,5,0
0,0,0,0,0,0,0,0,0,0,0,0,0,0,0,0,0,0,0
endlayer

layer
0,0,0,0,0,0,0,0,0,0,0,0,0,0,0,0,0,0,0
0,0,0,0,0,0,0,0,0,0,0,0,0,0,0,0,0,0,0
0,0,0,0,0,0,0,0,0,0,0,0,0,0,0,0,0,0,0
0,0,0,0,0,0,0,0,0,0,0,0,0,0,0,0,0,0,0
0,0,0,0,2,2,2,2,2,2,2,2,2,2,2,0,0,0,0
0,0,0,0,2,7,7,7,7,7,2,0,0,0,2,0,0,0,0
0,0,0,0,2,7,0,0,0,7,2,0,0,0,2,0,0,0,0
0,0,0,0,2,7,0,0,0,0,0,0,0,0,2,0,0,0,0
0,0,0,0,2,7,0,0,0,7,2,0,0,0,2,0,0,0,0
0,0,0,0,2,7,7,7,7,7,2,2,0,2,2,0,0,0,0
0,0,0,0,2,2,2,2,2,2,0,0,0,0,2,0,0,0,0
0,0,0,0,2,11,11,11,11,2,0,0,0,0,2,0,0,0,0
0,0,0,0,2,0,0,0,0,0,0,0,0,0,2,0,0,0,0
0,0,0,0,2,0,0,0,0,2,0,0,0,0,2,0,0,0,0
0,0,0,0,2,3,0,0,3,2,2,2,2,2,2,0,0,0,0
0,0,0,0,0,0,0,0,0,0,0,0,0,0,0,0,0,0,0
0,0,0,0,0,0,0,0,0,0,0,0,0,0,0,0,0,0,0
0,0,0,0,0,0,0,0,0,0,0,0,0,0,0,0,0,0,0
0,0,0,0,0,0,0,0,0,0,0,0,0,0,0,0,0,0,0
endlayer

layer
0,0,0,0,0,0,0,0,0,0,0,0,0,0,0,0,0,0,0
0,0,0,0,0,0,0,0,0,0,0,0,0,0,0,0,0,0,0
0,0,0,0,0,0,0,0,0,0,0,0,0,0,0,0,0,0,0
0,0,0,0,0,0,0,0,0,0,0,0,0,0,0,0,0,0,0
0,0,0,0,2,2,2,2,2,2,2,2,2,2,2,0,0,0,0
0,0,0,0,2,7,7,7,7,7,2,0,0,0,2,0,0,0,0
0,0,0,0,2,7,0,0,0,7,2,0,0,0,2,0,0,0,0
0,0,0,0,2,7,0,0,0,0,0,0,0,0,2,0,0,0,0
0,0,0,0,2,7,0,0,0,7,2,0,0,0,2,0,0,0,0
0,0,0,0,2,7,7,7,7,7,2,2,0,2,2,0,0,0,0
0,0,0,0,2,2,2,2,2,2,0,0,0,0,2,0,0,0,0
0,0,0,0,2,11,11,11,11,2,0,0,0,0,2,0,0,0,0
0,0,0,0,2,0,0,0,0,0,0,0,0,0,2,0,0,0,0
0,0,0,0,2,0,0,0,0,2,0,0,0,0,2,0,0,0,0
0,0,0,0,2,3,3,3,3,2,2,2,2,2,2,0,0,0,0
0,0,0,0,0,0,0,0,0,0,0,0,0,0,0,0,0,0,0
0,0,0,0,0,0,0,0,0,0,0,0,0,0,0,0,0,0,0
0,0,0,0,0,0,0,0,0,0,0,0,0,0,0,0,0,0,0
0,0,0,0,0,0,0,0,0,0,0,0,0,0,0,0,0,0,0
endlayer


layer
0,0,0,0,0,0,0,0,0,0,0,0,0,0,0,0,0,0,0
0,0,0,0,0,0,0,0,0,0,0,0,0,0,0,0,0,0,0
0,0,0,0,0,0,0,0,0,0,0,0,0,0,0,0,0,0,0
0,0,0,0,0,0,0,0,0,0,0,0,0,0,0,0,0,0,0
0,0,0,0,2,2,2,2,2,2,2,2,2,2,2,0,0,0,0
0,0,0,0,2,7,7,7,7,7,2,0,0,0,2,0,0,0,0
0,0,0,0,2,7,0,0,0,7,2,0,0,0,2,0,0,0,0
0,0,0,0,2,7,0,0,0,0,0,0,0,0,2,0,0,0,0
0,0,0,0,2,7,0,0,0,7,2,0,0,0,2,0,0,0,0
0,0,0,0,2,7,7,7,7,7,2,2,0,2,2,0,0,0,0
0,0,0,0,2,2,2,2,2,2,0,0,0,0,2,0,0,0,0
0,0,0,0,2,2,2,2,2,2,0,0,0,0,2,0,0,0,0
0,0,0,0,2,0,0,0,0,0,0,0,0,0,2,0,0,0,0
0,0,0,0,2,0,0,0,0,2,0,0,0,0,2,0,0,0,0
0,0,0,0,2,2,2,2,2,2,2,2,2,2,2,0,0,0,0
0,0,0,0,0,0,0,0,0,0,0,0,0,0,0,0,0,0,0
0,0,0,0,0,0,0,0,0,0,0,0,0,0,0,0,0,0,0
0,0,0,0,0,0,0,0,0,0,0,0,0,0,0,0,0,0,0
0,0,0,0,0,0,0,0,0,0,0,0,0,0,0,0,0,0,0
endlayer




#THE ROOF

layer
0,0,0,0,0,0,0,0,0,0,0,0,0,0,0,0,0,0,0
0,2,2,2,2,2,2,2,2,2,2,2,2,2,2,2,2,2,0
0,2,2,2,2,2,2,2,2,2,2,2,2,2,2,2,2,2,0
0,2,2,2,2,2,2,2,2,2,2,2,2,2,2,2,2,2,0
0,2,2,2,2,2,2,2,2,2,2,2,2,2,2,2,2,2,0
0,2,2,2,2,2,2,2,2,2,2,2,2,2,2,2,2,2,0
0,2,2,2,2,2,2,2,2,2,2,2,2,2,2,2,2,2,0
0,2,2,2,2,2,2,2,2,2,2,2,2,2,2,2,2,2,0
0,2,2,2,2,2,2,2,2,2,2,2,2,2,2,2,2,2,0
0,2,2,2,2,2,2,2,2,2,2,2,2,2,2,2,2,2,0
0,2,2,2,2,2,2,2,2,2,2,2,2,2,2,2,2,2,0
0,2,2,2,2,2,2,2,2,2,2,2,2,2,2,2,2,2,0
0,2,2,2,2,2,2,2,2,2,2,2,2,2,2,2,2,2,0
0,2,2,2,2,2,2,2,2,2,2,2,2,2,2,2,2,2,0
0,2,2,2,2,2,2,2,2,2,2,2,2,2,2,2,2,2,0
0,2,2,2,2,2,2,2,2,2,2,2,2,2,2,2,2,2,0
0,2,2,2,2,2,2,2,2,2,2,2,2,2,2,2,2,2,0
0,2,2,2,2,2,2,2,2,2,2,2,2,2,2,2,2,2,0
0,0,0,0,0,0,0,0,0,0,0,0,0,0,0,0,0,0,0
endlayer

layer
0,0,0,0,0,0,0,0,0,0,0,0,0,0,0,0,0,0,0
0,2,3,3,3,3,3,3,3,3,3,3,3,3,3,3,3,2,0
0,3,10,10,10,10,10,10,10,10,10,10,10,10,10,10,10,3,0
0,3,10,10,10,10,10,10,10,10,10,10,10,10,10,10,10,3,0
0,3,10,10,10,10,10,10,10,10,10,10,10,10,10,10,10,3,0
0,3,10,10,10,10,10,10,10,10,10,10,10,10,10,10,10,3,0
0,3,10,10,10,10,10,10,10,10,10,10,10,10,10,10,10,3,0
0,3,10,10,10,10,10,10,10,10,10,10,10,10,10,10,10,3,0
0,3,10,10,10,10,10,10,10,10,10,10,10,10,10,10,10,3,0
0,3,10,10,10,10,10,10,10,10,10,10,10,10,10,10,10,3,0
0,3,10,10,10,10,10,10,10,10,10,10,10,10,10,10,10,3,0
0,3,10,10,10,10,10,10,10,10,10,10,10,10,10,10,10,3,0
0,3,10,10,10,10,10,10,10,10,10,10,10,10,10,10,10,3,0
0,3,10,10,10,10,10,10,10,10,10,10,10,10,10,10,10,3,0
0,3,10,10,10,10,10,10,10,10,10,10,10,10,10,10,10,3,0
0,3,10,10,10,10,10,10,10,10,10,10,10,10,10,10,10,3,0
0,3,10,10,10,10,10,10,10,10,10,10,10,10,10,10,10,3,0
0,2,3,3,3,3,3,3,3,3,3,3,3,3,3,3,3,2,0
0,0,0,0,0,0,0,0,0,0,0,0,0,0,0,0,0,0,0
endlayer

layer
0,0,0,0,0,0,0,0,0,0,0,0,0,0,0,0,0,0,0
0,2,3,3,2,2,2,2,3,3,3,2,2,2,2,3,3,2,0
0,3,0,0,0,0,0,0,0,0,0,0,0,0,0,0,0,3,0
0,3,0,1,1,1,1,1,1,1,1,1,1,1,1,1,0,3,0
0,2,0,1,1,1,1,1,1,1,1,1,1,1,1,1,0,2,0
0,2,0,1,1,1,1,1,1,1,1,1,1,1,1,1,0,2,0
0,2,0,1,1,1,2,2,2,2,2,2,2,1,1,1,0,2,0
0,2,0,1,1,1,2,2,2,2,2,2,2,1,1,1,0,2,0
0,3,0,1,1,1,2,2,2,2,2,2,2,1,1,1,0,3,0
0,3,0,1,1,1,2,2,2,2,2,2,2,1,1,1,0,3,0
0,3,0,1,1,1,2,2,2,2,2,2,2,1,1,1,0,3,0
0,2,0,1,1,1,2,2,2,2,2,2,2,1,1,1,0,2,0
0,2,0,1,1,1,2,2,2,2,2,2,2,1,1,1,0,2,0
0,2,0,1,1,1,1,1,1,1,1,1,1,1,1,1,0,2,0
0,2,0,1,1,1,1,1,1,1,1,1,1,1,1,1,0,2,0
0,3,0,1,1,1,1,1,1,1,1,1,1,1,1,1,0,3,0
0,3,0,0,0,0,0,0,0,0,0,0,0,0,0,0,0,3,0
0,2,3,3,2,2,2,2,3,3,3,2,2,2,2,3,3,2,0
0,0,0,0,0,0,0,0,0,0,0,0,0,0,0,0,0,0,0
endlayer

layer
0,0,0,0,0,0,0,0,0,0,0,0,0,0,0,0,0,0,0
0,2,3,2,2,0,0,2,2,3,2,2,0,0,2,2,3,2,0
0,3,0,0,0,0,0,0,0,0,0,0,0,0,0,0,0,3,0
0,2,0,0,0,0,0,0,0,0,0,0,0,0,0,0,0,2,0
0,2,0,0,1,1,1,1,1,1,1,1,1,1,1,0,0,2,0
0,0,0,0,1,1,1,1,1,1,1,1,1,1,1,0,0,0,0
0,0,0,0,1,1,2,2,2,2,2,2,2,1,1,0,0,0,0
0,2,0,0,1,1,2,2,2,2,2,2,2,1,1,0,0,2,0
0,2,0,0,1,1,2,2,2,2,2,2,2,1,1,0,0,2,0
0,3,0,0,1,1,2,2,2,2,2,2,2,1,1,0,0,3,0
0,2,0,0,1,1,2,2,2,2,2,2,2,1,1,0,0,2,0
0,2,0,0,1,1,2,2,2,2,2,2,2,1,1,0,0,2,0
0,0,0,0,1,1,2,2,2,2,2,2,2,1,1,0,0,0,0
0,0,0,0,1,1,1,1,1,1,1,1,1,1,1,0,0,0,0
0,2,0,0,1,1,1,1,1,1,1,1,1,1,1,0,0,2,0
0,2,0,0,0,0,0,0,0,0,0,0,0,0,0,0,0,2,0
0,3,0,0,0,0,0,0,0,0,0,0,0,0,0,0,0,3,0
0,2,3,2,2,0,0,2,2,3,2,2,0,0,2,2,3,2,0
0,0,0,0,0,0,0,0,0,0,0,0,0,0,0,0,0,0,0
endlayer

layer
0,0,0,0,0,0,0,0,0,0,0,0,0,0,0,0,0,0,0
0,2,2,2,0,0,0,0,2,2,2,0,0,0,0,2,2,2,0
0,2,0,0,0,0,0,0,0,0,0,0,0,0,0,0,0,2,0
0,2,0,0,0,0,0,0,0,0,0,0,0,0,0,0,0,2,0
0,0,0,0,0,0,0,0,0,0,0,0,0,0,0,0,0,0,0
0,0,0,0,0,1,1,1,1,1,1,1,1,1,0,0,0,0,0
0,0,0,0,0,1,2,2,2,2,2,2,2,1,0,0,0,0,0
0,0,0,0,0,1,2,2,2,2,2,2,2,1,0,0,0,0,0
0,2,0,0,0,1,2,2,2,2,2,2,2,1,0,0,0,2,0
0,2,0,0,0,1,2,2,2,2,2,2,2,1,0,0,0,2,0
0,2,0,0,0,1,2,2,2,2,2,2,2,1,0,0,0,2,0
0,0,0,0,0,1,2,2,2,2,2,2,2,1,0,0,0,0,0
0,0,0,0,0,1,2,2,2,2,2,2,2,1,0,0,0,0,0
0,0,0,0,0,1,1,1,1,1,1,1,1,1,0,0,0,0,0
0,0,0,0,0,0,0,0,0,0,0,0,0,0,0,0,0,0,0
0,2,0,0,0,0,0,0,0,0,0,0,0,0,0,0,0,2,0
0,2,0,0,0,0,0,0,0,0,0,0,0,0,0,0,0,2,0
0,2,2,2,0,0,0,0,2,2,2,0,0,0,0,2,2,2,0
0,0,0,0,0,0,0,0,0,0,0,0,0,0,0,0,0,0,0
endlayer

layer
0,0,0,0,0,0,0,0,0,0,0,0,0,0,0,0,0,0,0
0,2,2,0,0,0,0,0,0,2,0,0,0,0,0,0,2,2,0
0,2,0,0,0,0,0,0,0,0,0,0,0,0,0,0,0,2,0
0,0,0,0,0,0,0,0,0,0,0,0,0,0,0,0,0,0,0
0,0,0,0,0,0,0,0,0,0,0,0,0,0,0,0,0,0,0
0,0,0,0,0,0,0,0,0,0,0,0,0,0,0,0,0,0,0
0,0,0,0,0,0,1,1,1,1,1,1,1,0,0,0,0,0,0
0,0,0,0,0,0,1,2,2,2,2,2,1,0,0,0,0,0,0
0,0,0,0,0,0,1,2,2,2,2,2,1,0,0,0,0,0,0
0,0,0,0,0,0,1,2,2,2,2,2,1,0,0,0,0,2,0
0,2,0,0,0,0,1,2,2,2,2,2,1,0,0,0,0,0,0
0,0,0,0,0,0,1,2,2,2,2,2,1,0,0,0,0,0,0
0,0,0,0,0,0,1,1,1,1,1,1,1,0,0,0,0,0,0
0,0,0,0,0,0,0,0,0,0,0,0,0,0,0,0,0,0,0
0,0,0,0,0,0,0,0,0,0,0,0,0,0,0,0,0,0,0
0,0,0,0,0,0,0,0,0,0,0,0,0,0,0,0,0,0,0
0,2,0,0,0,0,0,0,0,0,0,0,0,0,0,0,0,2,0
0,2,2,0,0,0,0,0,0,2,0,0,0,0,0,0,2,2,0
0,0,0,0,0,0,0,0,0,0,0,0,0,0,0,0,0,0,0
endlayer

layer
0,0,0,0,0,0,0,0,0,0,0,0,0,0,0,0,0,0,0
0,2,0,0,0,0,0,0,0,0,0,0,0,0,0,0,0,2,0
0,0,0,0,0,0,0,0,0,0,0,0,0,0,0,0,0,0,0
0,0,0,0,0,0,0,0,0,0,0,0,0,0,0,0,0,0,0
0,0,0,0,0,0,0,0,0,0,0,0,0,0,0,0,0,0,0
0,0,0,0,0,0,0,0,0,0,0,0,0,0,0,0,0,0,0
0,0,0,0,0,0,0,0,0,0,0,0,0,0,0,0,0,0,0
0,0,0,0,0,0,0,1,1,1,1,1,0,0,0,0,0,0,0
0,0,0,0,0,0,0,1,2,2,2,1,0,0,0,0,0,0,0
0,0,0,0,0,0,0,1,2,2,2,1,0,0,0,0,0,0,0
0,0,0,0,0,0,0,1,2,2,2,1,0,0,0,0,0,0,0
0,0,0,0,0,0,0,1,1,1,1,1,0,0,0,0,0,0,0
0,0,0,0,0,0,0,0,0,0,0,0,0,0,0,0,0,0,0
0,0,0,0,0,0,0,0,0,0,0,0,0,0,0,0,0,0,0
0,0,0,0,0,0,0,0,0,0,0,0,0,0,0,0,0,0,0
0,0,0,0,0,0,0,0,0,0,0,0,0,0,0,0,0,0,0
0,0,0,0,0,0,0,0,0,0,0,0,0,0,0,0,0,0,0
0,2,0,0,0,0,0,0,0,0,0,0,0,0,0,0,0,2,0
0,0,0,0,0,0,0,0,0,0,0,0,0,0,0,0,0,0,0
endlayer

layer
0,0,0,0,0,0,0,0,0,0,0,0,0,0,0,0,0,0,0
0,0,0,0,0,0,0,0,0,0,0,0,0,0,0,0,0,0,0
0,0,0,0,0,0,0,0,0,0,0,0,0,0,0,0,0,0,0
0,0,0,0,0,0,0,0,0,0,0,0,0,0,0,0,0,0,0
0,0,0,0,0,0,0,0,0,0,0,0,0,0,0,0,0,0,0
0,0,0,0,0,0,0,0,0,0,0,0,0,0,0,0,0,0,0
0,0,0,0,0,0,0,0,0,0,0,0,0,0,0,0,0,0,0
0,0,0,0,0,0,0,0,0,0,0,0,0,0,0,0,0,0,0
0,0,0,0,0,0,0,0,1,1,1,0,0,0,0,0,0,0,0
0,0,0,0,0,0,0,0,1,1,1,0,0,0,0,0,0,0,0
0,0,0,0,0,0,0,0,1,1,1,0,0,0,0,0,0,0,0
0,0,0,0,0,0,0,0,0,0,0,0,0,0,0,0,0,0,0
0,0,0,0,0,0,0,0,0,0,0,0,0,0,0,0,0,0,0
0,0,0,0,0,0,0,0,0,0,0,0,0,0,0,0,0,0,0
0,0,0,0,0,0,0,0,0,0,0,0,0,0,0,0,0,0,0
0,0,0,0,0,0,0,0,0,0,0,0,0,0,0,0,0,0,0
0,0,0,0,0,0,0,0,0,0,0,0,0,0,0,0,0,0,0
0,0,0,0,0,0,0,0,0,0,0,0,0,0,0,0,0,0,0
0,0,0,0,0,0,0,0,0,0,0,0,0,0,0,0,0,0,0
endlayer
