#BASICS

weight=7
embed_into_distance=0
acceptable_target_blocks=1,2,3,12,13,49,79,110
dimensions=35,19,19
allowable_overhang=270
max_cut_in=5
cut_in_buffer=1
max_leveling=2
leveling_buffer=1
preserve_water=0
preserve_lava=0
preserve_plants=0

#RULES LIST - SETS BLOCK NUMBERS

rule1=0,100,49
rule2=0,100,24
rule3=0,100,72
rule4=0,100,47
rule5=0,100,85
rule6=0,100,65-3
rule7=0,100,65-2
rule8=0,100,302
rule9=0,100,44-1
rule10=0,100,309
rule11=0,100,303

#MY LIST OF BLOCKS

#     0 = AIR
#     1 = Obsidian
#     2 = Sandstone
#     3 = Pressure Plate
#     4 = Books
#     5 = Fencepost
#     6 = Right Ladder
#     7 = Left Ladder
#     8 = Skelly Spawner
#     9 = Sand-Slab
#     10 = Chest
#     11 =Spiders

#     300 = Leave existing world block alone
#     301 = Mob Spawner (Zombie)
#     302 = Mob Spawner (Skeleton) 
#     303 = Mob Spawner (Spider)
#     304 = Mob Spawner (Creeper)
#     305 = Mob Spawner (Zombie, Skeleton, Creeper)
#     306 = Mob Spawner (Easy, zombies and skeletons)
#     307 = Mob Spawner (Medium, zombies, skeletons, and spiders)
#     308 = Mob Spawner (Hard, all mobs)
#     309 = Easy Chest (For Easy rewards)
#     310 = Medium Chest (For Medium rewards)
#     311 = Hard Chest (For Hard rewards)


# LAYERS
# Each layer is a comma-delimited list of rules, one for each block.  There
# must be as many layers as the height, and each layer must have "layer" before
# the rules and end with "endlayer".  There are as many rows as the length, and
# as many rules as the width.  If you want the block blanked out use 0, which
# represents the Air-block rule.


#Foundation Layers 1,2

layer
2,2,2,2,2,2,2,2,2,2,2,2,2,2,2,2,2,2,2
2,2,2,2,2,2,2,2,2,2,2,2,2,2,2,2,2,2,2
2,2,2,2,2,2,2,2,2,2,2,2,2,2,2,2,2,2,2
2,2,2,2,2,2,2,2,2,2,2,2,2,2,2,2,2,2,2
2,2,2,2,2,2,2,2,2,2,2,2,2,2,2,2,2,2,2
2,2,2,2,2,2,2,2,2,2,2,7,2,2,2,2,2,2,2
2,2,2,2,2,2,2,2,2,2,2,2,2,2,2,2,2,2,2
2,2,2,2,2,2,2,2,2,2,2,2,2,2,2,2,2,2,2
2,2,2,2,2,2,2,2,2,2,2,2,2,2,2,2,2,2,2
2,2,2,2,2,2,2,2,7,2,2,2,2,2,2,2,2,2,2
2,2,2,2,2,2,2,2,2,2,2,2,2,2,2,2,2,2,2
2,2,2,2,2,2,2,2,2,2,2,2,2,2,2,2,2,2,2
2,2,2,2,2,2,2,2,2,2,2,2,2,2,2,2,2,2,2
2,2,2,2,2,2,2,2,2,2,2,2,2,2,2,2,2,2,2
2,2,2,2,2,2,2,2,2,2,7,2,2,2,2,2,2,2,2
2,2,2,2,2,2,2,2,2,2,2,2,2,2,2,2,2,2,2
2,2,2,2,2,2,2,2,2,2,2,2,2,2,2,2,2,2,2
2,2,2,2,2,2,2,2,2,2,2,2,2,2,2,2,2,2,2
2,2,2,2,2,2,2,2,2,2,2,2,2,2,2,2,2,2,2
endlayer

layer
2,2,2,2,0,0,0,0,0,0,0,0,0,0,0,2,2,2,2
2,1,1,1,1,1,9,9,9,9,9,9,9,1,1,1,1,1,2
2,1,2,2,2,2,2,2,2,2,2,2,2,2,2,2,2,1,2
2,1,2,1,2,1,2,1,2,1,2,1,2,1,2,1,2,1,2
0,1,2,2,1,2,1,2,1,2,1,2,1,2,1,2,2,1,0
0,1,2,1,2,1,2,1,2,1,2,1,2,1,2,1,2,1,0
0,9,2,2,1,2,1,2,1,2,1,2,1,2,1,2,2,9,0
0,9,2,1,2,1,2,1,2,1,2,1,2,1,2,1,2,9,0
0,9,2,2,1,2,1,2,1,2,1,2,1,2,1,2,2,9,0
0,9,2,1,2,1,2,1,2,1,2,1,2,1,2,1,2,9,0
0,9,2,2,1,2,1,2,1,2,1,2,1,2,1,2,2,9,0
0,9,2,1,2,1,2,1,2,1,2,1,2,1,2,1,2,9,0
0,9,2,2,1,2,1,2,1,2,1,2,1,2,1,2,2,9,0
0,1,2,1,2,1,2,1,2,1,2,1,2,1,2,1,2,1,0
0,1,2,2,1,2,1,2,1,2,1,2,1,2,1,2,2,1,0
2,1,2,1,2,1,2,1,2,1,2,1,2,1,2,1,2,1,2
2,1,2,2,2,2,2,2,2,2,2,2,2,2,2,2,2,1,2
2,1,1,1,1,1,9,9,9,9,9,9,9,1,1,1,1,1,2
2,2,2,2,0,0,0,0,0,0,0,0,0,0,0,2,2,2,2
endlayer

#Door Layer 3, 4, 5

layer
2,2,2,2,0,0,0,0,0,0,0,0,0,0,0,2,2,2,2
2,1,1,1,1,1,0,0,0,0,0,0,0,1,1,1,1,1,2
2,1,2,2,2,2,2,2,2,2,2,2,2,2,2,2,2,1,2
2,1,2,7,0,0,5,5,5,5,5,5,5,0,0,6,2,1,2
0,1,2,2,0,0,0,0,0,0,0,0,0,0,0,2,2,1,0
0,1,2,5,0,0,0,0,0,0,0,0,0,0,0,5,2,1,0
0,0,2,5,0,0,2,2,2,0,2,2,2,0,0,5,2,0,0
0,0,2,5,0,0,2,0,0,0,0,0,2,0,0,5,2,0,0
0,0,2,5,0,0,2,0,0,0,0,0,2,0,0,5,2,0,0
0,0,2,5,0,0,2,0,0,5,0,0,2,0,0,5,2,0,0
0,0,2,5,0,0,2,0,0,0,0,0,2,0,0,5,2,0,0
0,0,2,5,0,0,2,0,0,0,0,0,2,0,0,5,2,0,0
0,0,2,5,0,0,2,2,2,2,2,2,2,0,0,5,2,0,0
0,1,2,5,0,0,0,0,0,0,0,0,0,0,0,5,2,1,0
0,1,2,0,0,0,0,0,0,0,0,0,0,0,0,0,2,1,0
2,1,2,0,0,0,0,0,0,0,0,0,0,0,0,0,2,1,2
2,1,2,2,2,2,2,2,0,0,0,2,2,2,2,2,2,1,2
2,1,1,1,1,1,0,0,0,0,0,0,0,1,1,1,1,1,2
2,2,2,2,0,0,0,0,0,0,0,0,0,0,0,2,2,2,2
endlayer

layer
2,2,2,2,0,0,0,0,0,0,0,0,0,0,0,2,2,2,2
2,1,1,1,1,1,0,0,0,0,0,0,0,1,1,1,1,1,2
2,1,2,2,2,2,2,2,2,2,2,2,2,2,2,2,2,1,2
2,1,2,7,0,0,3,3,3,3,3,3,3,0,0,6,2,1,2
0,1,2,2,0,0,0,0,0,0,0,0,0,0,0,2,2,1,0
0,1,2,3,0,0,0,0,0,0,0,0,0,0,0,3,2,1,0
0,0,2,3,0,0,4,4,2,0,2,4,4,0,0,3,2,0,0
0,0,2,3,0,0,4,0,0,0,0,0,4,0,0,3,2,0,0
0,0,2,3,0,0,4,0,0,0,0,0,4,0,0,3,2,0,0
0,0,2,3,0,0,4,0,0,8,0,0,4,0,0,3,2,0,0
0,0,2,3,0,0,4,0,0,0,0,0,4,0,0,3,2,0,0
0,0,2,3,0,0,4,0,0,0,0,0,4,0,0,3,2,0,0
0,0,2,3,0,0,4,4,4,4,4,4,4,0,0,3,2,0,0
0,1,2,3,0,0,0,0,0,0,0,0,0,0,0,3,2,1,0
0,1,2,0,0,0,0,0,0,0,0,0,0,0,0,0,2,1,0
2,1,2,0,0,0,0,0,0,0,0,0,0,0,0,0,2,1,2
2,1,2,2,2,2,2,2,0,0,0,2,2,2,2,2,2,1,2
2,1,1,1,1,1,0,0,0,0,0,0,0,1,1,1,1,1,2
2,2,2,2,0,0,0,0,0,0,0,0,0,0,0,2,2,2,2
endlayer

layer
2,2,2,2,0,0,0,0,0,0,0,0,0,0,0,2,2,2,2
2,1,1,1,1,1,0,0,0,0,0,0,0,1,1,1,1,1,2
2,1,2,2,2,2,2,2,2,2,2,2,2,2,2,2,2,1,2
2,1,2,7,0,0,0,0,0,0,0,0,0,0,0,6,2,1,2
0,1,2,2,0,0,0,0,0,0,0,0,0,0,0,2,2,1,0
0,1,2,0,0,0,0,0,0,0,0,0,0,0,0,0,2,1,0
0,0,2,0,0,0,4,4,2,0,2,4,4,0,0,0,2,0,0
0,0,2,0,0,0,4,0,0,0,0,0,4,0,0,0,2,0,0
0,0,2,0,0,0,4,0,0,0,0,0,4,0,0,0,2,0,0
0,0,2,0,0,0,4,0,0,0,0,0,4,0,0,0,2,0,0
0,0,2,0,0,0,4,0,0,0,0,0,4,0,0,0,2,0,0
0,0,2,0,0,0,4,0,0,0,0,0,4,0,0,0,2,0,0
0,0,2,0,0,0,4,4,4,4,4,4,4,0,0,0,2,0,0
0,1,2,0,0,0,0,0,0,0,0,0,0,0,0,0,2,1,0
0,1,2,0,0,0,0,0,0,0,0,0,0,0,0,0,2,1,0
2,1,2,0,0,0,0,0,0,0,0,0,0,0,0,0,2,1,2
2,1,2,2,2,2,2,2,0,0,0,2,2,2,2,2,2,1,2
2,1,1,1,1,1,0,0,0,0,0,0,0,1,1,1,1,1,2
2,2,2,2,0,0,0,0,0,0,0,0,0,0,0,2,2,2,2
endlayer

#Tower Layer 6-7

layer
2,2,2,2,0,0,0,0,0,0,0,0,0,0,0,2,2,2,2
2,1,1,1,1,1,0,0,0,0,0,0,0,1,1,1,1,1,2
2,1,2,2,2,2,2,2,2,2,2,2,2,2,2,2,2,1,2
2,1,2,7,0,0,0,0,0,0,0,0,0,0,0,6,2,1,2
0,1,2,2,0,0,0,0,0,0,0,0,0,0,0,2,2,1,0
0,1,2,0,0,0,0,0,0,0,0,0,0,0,0,0,2,1,0
0,0,2,0,0,0,4,4,2,2,2,4,4,0,0,0,2,0,0
0,0,2,0,0,0,4,0,0,0,0,0,4,0,0,0,2,0,0
0,0,2,0,0,0,4,0,0,0,0,0,4,0,0,0,2,0,0
0,0,2,0,0,0,4,0,0,0,0,0,4,0,0,0,2,0,0
0,0,2,0,0,0,4,0,0,0,0,0,4,0,0,0,2,0,0
0,0,2,0,0,0,4,0,0,0,0,0,4,0,0,0,2,0,0
0,0,2,0,0,0,4,4,4,4,4,4,4,0,0,0,2,0,0
0,1,2,0,0,0,0,0,0,0,0,0,0,0,0,0,2,1,0
0,1,2,0,0,0,0,0,0,0,0,0,0,0,0,0,2,1,0
2,1,2,0,0,0,0,0,0,0,0,0,0,0,0,0,2,1,2
2,1,2,2,2,2,2,2,2,2,2,2,2,2,2,2,2,1,2
2,1,1,1,1,1,0,0,0,0,0,0,0,1,1,1,1,1,2
2,2,2,2,0,0,0,0,0,0,0,0,0,0,0,2,2,2,2
endlayer

layer
2,2,2,2,0,0,0,0,0,0,0,0,0,0,0,2,2,2,2
2,1,1,1,1,1,0,0,0,0,0,0,0,1,1,1,1,1,2
2,1,2,2,2,2,2,2,2,2,2,2,2,2,2,2,2,1,2
2,1,2,7,0,0,0,0,0,0,0,0,0,0,0,6,2,1,2
0,1,2,2,0,0,0,0,0,0,0,0,0,0,0,2,2,1,0
0,1,2,0,0,0,0,0,0,0,0,0,0,0,0,0,2,1,0
0,0,2,0,0,0,2,2,2,2,2,2,2,0,0,0,2,0,0
0,0,2,0,0,0,2,2,2,2,2,2,2,0,0,0,2,0,0
0,0,2,0,0,0,2,2,2,2,2,2,2,0,0,0,2,0,0
0,0,2,0,0,0,2,2,2,2,2,2,2,0,0,0,2,0,0
0,0,2,0,0,0,2,2,2,2,2,2,2,0,0,0,2,0,0
0,0,2,0,0,0,2,2,2,2,2,2,2,0,0,0,2,0,0
0,0,2,0,0,0,2,2,2,2,2,2,2,0,0,0,2,0,0
0,1,2,0,0,0,0,0,0,0,0,0,0,0,0,0,2,1,0
0,1,2,0,0,0,0,0,0,0,0,0,0,0,0,0,2,1,0
2,1,2,0,0,0,0,0,0,0,0,0,0,0,0,0,2,1,2
2,1,2,2,2,2,2,2,2,2,2,2,2,2,2,2,2,1,2
2,1,1,1,1,1,0,0,0,0,0,0,0,1,1,1,1,1,2
2,2,2,2,0,0,0,0,0,0,0,0,0,0,0,2,2,2,2
endlayer

# Second floor-Floor; layer 8

layer
2,2,2,2,0,0,0,0,0,0,0,0,0,0,0,2,2,2,2
2,1,1,1,1,1,0,0,0,0,0,0,0,1,1,1,1,1,2
2,1,2,2,2,2,2,2,2,2,2,2,2,2,2,2,2,1,2
2,1,2,7,2,1,2,1,2,1,2,1,2,1,2,6,2,1,2
0,1,2,2,1,2,1,2,1,2,1,2,1,2,1,2,2,1,0
0,1,2,1,2,1,2,1,2,1,2,1,2,1,2,1,2,1,0
0,0,2,2,1,2,1,2,1,2,1,2,1,2,1,2,2,0,0
0,0,2,1,2,1,2,1,2,1,2,1,2,1,2,1,2,0,0
0,0,2,2,1,2,1,2,1,2,1,2,1,2,1,2,2,0,0
0,0,2,1,2,1,2,1,2,1,2,1,2,1,2,1,2,0,0
0,0,2,2,1,2,1,2,1,2,1,2,1,2,1,2,2,0,0
0,0,2,1,2,1,2,1,2,1,2,1,2,1,2,1,2,0,0
0,0,2,2,1,2,1,2,1,2,1,2,1,2,1,2,2,0,0
0,1,2,1,2,1,2,1,2,1,2,1,2,1,2,1,2,1,0
0,1,2,2,1,2,1,2,1,2,1,2,1,2,1,2,2,1,0
2,1,2,1,2,1,2,1,2,1,2,1,2,1,2,1,2,1,2
2,1,2,2,2,2,2,2,2,2,2,2,2,2,2,2,2,1,2
2,1,1,1,1,1,0,0,0,0,0,0,0,1,1,1,1,1,2
2,2,2,2,0,0,0,0,0,0,0,0,0,0,0,2,2,2,2
endlayer

#Arch Layers layers 9 - 17

layer
2,2,2,2,0,0,0,0,0,0,0,0,0,0,0,2,2,2,2
2,1,1,1,1,1,1,0,0,0,0,0,1,1,1,1,1,1,2
2,1,2,2,2,2,2,2,2,2,2,2,2,2,2,2,2,1,2
2,1,2,7,0,0,0,0,0,0,0,0,0,0,0,6,2,1,2
0,1,2,2,0,0,0,0,0,0,0,0,0,0,0,2,2,1,0
0,1,2,0,0,0,0,0,0,0,0,0,0,0,0,0,2,1,0
0,1,2,0,0,0,2,2,2,0,2,2,2,0,0,0,2,1,0
0,0,2,0,0,0,2,0,0,0,0,0,2,0,0,0,2,0,0
0,0,2,0,0,0,2,0,0,0,0,0,2,0,0,0,2,0,0
0,0,2,0,0,0,2,0,0,5,0,0,2,0,0,0,2,0,0
0,0,2,0,0,0,2,0,0,0,0,0,2,0,0,0,2,0,0
0,0,2,0,0,0,2,0,0,0,0,0,2,0,0,0,2,0,0
0,1,2,0,0,0,2,2,2,2,2,2,2,0,0,0,2,1,0
0,1,2,0,0,0,0,0,0,0,0,0,0,0,0,0,2,1,0
0,1,2,0,0,0,0,0,0,0,0,0,0,0,0,0,2,1,0
2,1,2,0,0,0,0,0,0,0,0,0,0,0,0,0,2,1,2
2,1,2,2,2,2,2,2,2,2,2,2,2,2,2,2,2,1,2
2,1,1,1,1,1,1,0,0,0,0,0,1,1,1,1,1,1,2
2,2,2,2,0,0,0,0,0,0,0,0,0,0,0,2,2,2,2
endlayer

layer
2,2,2,2,0,0,0,0,0,0,0,0,0,0,0,2,2,2,2
2,1,1,1,1,1,1,1,0,0,0,1,1,1,1,1,1,1,2
2,1,2,2,2,2,2,2,2,2,2,2,2,2,2,2,2,1,2
2,1,2,7,0,0,0,0,0,0,0,0,0,0,0,6,2,1,2
0,1,2,2,0,0,0,0,0,0,0,0,0,0,0,2,2,1,0
0,1,2,0,0,0,0,0,0,0,0,0,0,0,0,0,2,1,0
0,1,2,0,0,0,4,4,2,0,2,4,4,0,0,0,2,1,0
0,1,2,0,0,0,4,0,0,0,0,0,4,0,0,0,2,1,0
0,0,2,0,0,0,4,0,0,0,0,0,4,0,0,0,2,0,0
0,0,2,0,0,0,4,0,0,5,0,0,4,0,0,0,2,0,0
0,0,2,0,0,0,4,0,0,0,0,0,4,0,0,0,2,0,0
0,1,2,0,0,0,4,0,0,0,0,0,4,0,0,0,2,1,0
0,1,2,0,0,0,4,4,4,4,4,4,4,0,0,0,2,1,0
0,1,2,0,0,0,0,0,0,0,0,0,0,0,0,0,2,1,0
0,1,2,0,0,0,0,0,0,0,0,0,0,0,0,0,2,1,0
2,1,2,0,0,0,0,0,0,0,0,0,0,0,0,0,2,1,2
2,1,2,2,2,2,2,2,2,2,2,2,2,2,2,2,2,1,2
2,1,1,1,1,1,1,1,0,0,0,1,1,1,1,1,1,1,2
2,2,2,2,0,0,0,0,0,0,0,0,0,0,0,2,2,2,2
endlayer

layer
2,2,2,2,2,0,0,0,0,0,0,0,0,0,2,2,2,2,2
2,1,1,1,1,1,1,1,1,1,1,1,1,1,1,1,1,1,2
2,1,2,2,2,2,2,2,2,2,2,2,2,2,2,2,2,1,2
2,1,2,7,0,0,0,0,0,0,0,0,0,0,0,6,2,1,2
2,1,2,2,0,0,0,0,0,0,0,0,0,0,0,2,2,1,2
0,1,2,0,0,0,0,0,0,0,0,0,0,0,0,0,2,1,0
0,1,2,0,0,0,4,4,2,0,2,4,4,0,0,0,2,1,0
0,1,2,0,0,0,4,0,0,0,0,0,4,0,0,0,2,1,0
0,1,2,0,0,0,4,0,0,0,0,0,4,0,0,0,2,1,0
0,1,2,0,0,0,4,0,0,5,0,0,4,0,0,0,2,1,0
0,1,2,0,0,0,4,0,0,0,0,0,4,0,0,0,2,1,0
0,1,2,0,0,0,4,0,0,0,0,0,4,0,0,0,2,1,0
0,1,2,0,0,0,4,4,4,4,4,4,4,0,0,0,2,1,0
0,1,2,0,0,0,0,0,0,0,0,0,0,0,0,0,2,1,0
2,1,2,0,0,0,0,0,0,0,0,0,0,0,0,0,2,1,2
2,1,2,0,0,0,0,0,0,0,0,0,0,0,0,0,2,1,2
2,1,2,2,2,2,2,2,2,2,2,2,2,2,2,2,2,1,2
2,1,1,1,1,1,1,1,1,1,1,1,1,1,1,1,1,1,2
2,2,2,2,2,0,0,0,0,0,0,0,0,0,2,2,2,2,2
endlayer

layer
2,2,2,2,2,2,0,0,0,0,0,0,0,2,2,2,2,2,2
2,1,1,1,1,1,1,1,1,1,1,1,1,1,1,1,1,1,2
2,1,2,2,2,2,2,2,2,2,2,2,2,2,2,2,2,1,2
2,1,2,7,0,0,0,0,0,0,0,0,0,0,0,6,2,1,2
2,1,2,2,0,0,0,0,0,0,0,0,0,0,0,2,2,1,2
2,1,2,0,0,0,0,0,0,0,0,0,0,0,0,0,2,1,2
0,1,2,0,0,0,4,4,2,2,2,4,4,0,0,0,2,1,0
0,1,2,0,0,0,4,0,0,0,0,0,4,0,0,0,2,1,0
0,1,2,0,0,0,4,0,0,0,0,0,4,0,0,0,2,1,0
0,1,2,0,0,0,4,0,0,5,0,0,4,0,0,0,2,1,0
0,1,2,0,0,0,4,0,0,0,0,0,4,0,0,0,2,1,0
0,1,2,0,0,0,4,0,0,0,0,0,4,0,0,0,2,1,0
0,1,2,0,0,0,4,4,4,4,4,4,4,0,0,0,2,1,0
2,1,2,0,0,0,0,0,0,0,0,0,0,0,0,0,2,1,2
2,1,2,0,0,0,0,0,0,0,0,0,0,0,0,0,2,1,2
2,1,2,0,0,0,0,0,0,0,0,0,0,0,0,0,2,1,2
2,1,2,2,2,2,2,2,2,2,2,2,2,2,2,2,2,1,2
2,1,1,1,1,1,1,1,1,1,1,1,1,1,1,1,1,1,2
2,2,2,2,2,2,0,0,0,0,0,0,0,2,2,2,2,2,2
endlayer

layer
2,2,2,2,2,2,2,0,0,0,0,0,2,2,2,2,2,2,2
2,1,1,1,1,1,1,1,1,1,1,1,1,1,1,1,1,1,2
2,1,2,2,2,2,2,2,2,2,2,2,2,2,2,2,2,1,2
2,1,2,7,0,0,0,0,0,0,0,0,0,0,0,6,2,1,2
2,1,2,2,0,0,0,0,0,0,0,0,0,0,0,2,2,1,2
2,1,2,0,0,0,0,0,0,0,0,0,0,0,0,0,2,1,2
2,1,2,0,0,0,2,2,2,2,2,2,2,0,0,0,2,1,2
0,1,2,0,0,0,2,2,2,2,2,2,2,0,0,0,2,1,0
0,1,2,0,0,0,2,2,2,2,2,2,2,0,0,0,2,1,0
0,1,2,0,0,0,2,2,2,2,2,2,2,0,0,0,2,1,0
0,1,2,0,0,0,2,2,2,2,2,2,2,0,0,0,2,1,0
0,1,2,0,0,0,2,2,2,2,2,2,2,0,0,0,2,1,0
2,1,2,0,0,0,2,2,2,2,2,2,2,0,0,0,2,1,2
2,1,2,0,0,0,0,0,0,0,0,0,0,0,0,0,2,1,2
2,1,2,0,0,0,0,0,0,0,0,0,0,0,0,0,2,1,2
2,1,2,0,0,0,0,0,0,0,0,0,0,0,0,0,2,1,2
2,1,2,2,2,2,2,2,2,2,2,2,2,2,2,2,2,1,2
2,1,1,1,1,1,1,1,1,1,1,1,1,1,1,1,1,1,2
2,2,2,2,2,2,2,0,0,0,0,0,2,2,2,2,2,2,2
endlayer

# Still tower, but 3rd floor

layer
2,2,2,2,2,2,2,2,0,0,0,2,2,2,2,2,2,2,2
2,1,1,1,1,1,1,1,1,1,1,1,1,1,1,1,1,1,2
2,1,2,2,2,2,2,2,2,2,2,2,2,2,2,2,2,1,2
2,1,2,7,1,2,1,2,1,2,1,2,1,2,1,6,2,1,2
2,1,2,1,2,1,2,1,2,1,2,1,2,1,2,1,2,1,2
2,1,2,2,1,2,1,2,1,2,1,2,1,2,1,2,2,1,2
2,1,2,1,2,1,2,1,2,1,2,1,2,1,2,1,2,1,2
2,1,2,2,1,2,1,2,1,2,1,2,1,2,1,2,2,1,2
0,1,2,1,2,1,2,1,2,1,2,1,2,1,2,1,2,1,0
0,1,2,2,1,2,1,2,1,2,1,2,1,2,1,2,2,1,0
0,1,2,1,2,1,2,1,2,1,2,1,2,1,2,1,2,1,0
2,1,2,2,1,2,1,2,1,2,1,2,1,2,1,2,2,1,2
2,1,2,1,2,1,2,1,2,1,2,1,2,1,2,1,2,1,2
2,1,2,2,1,2,1,2,1,2,1,2,1,2,1,2,2,1,2
2,1,2,1,2,1,2,1,2,1,2,1,2,1,2,1,2,1,2
2,1,2,2,1,2,1,2,1,2,1,2,1,2,1,2,2,1,2
2,1,2,2,2,2,2,2,2,2,2,2,2,2,2,2,2,1,2
2,1,1,1,1,1,1,1,1,1,1,1,1,1,1,1,1,1,2
2,2,2,2,2,2,2,2,0,0,0,2,2,2,2,2,2,2,2
endlayer

layer
2,2,2,2,2,2,2,2,2,2,2,2,2,2,2,2,2,2,2
2,1,1,1,1,1,1,1,1,1,1,1,1,1,1,1,1,1,2
2,1,2,2,2,2,2,2,2,2,2,2,2,2,2,2,2,1,2
2,1,2,0,0,10,0,10,0,10,0,10,0,10,0,0,2,1,2
2,1,2,0,0,0,0,0,0,0,0,0,0,0,0,0,2,1,2
2,1,2,10,0,0,0,0,0,0,0,0,0,0,0,10,2,1,2
2,1,2,0,0,0,0,0,0,0,0,0,0,0,0,0,2,1,2
2,1,2,10,0,0,0,0,0,0,0,0,0,0,0,10,2,1,2
2,1,2,0,0,0,0,0,0,0,0,0,0,0,0,0,2,1,2
2,1,2,10,0,0,0,0,0,5,0,0,0,0,0,10,2,1,2
2,1,2,0,0,0,0,0,0,0,0,0,0,0,0,0,2,1,2
2,1,2,10,0,0,0,0,0,0,0,0,0,0,0,10,2,1,2
2,1,2,0,0,0,0,0,0,0,0,0,0,0,0,0,2,1,2
2,1,2,10,0,0,0,0,0,0,0,0,0,0,0,10,2,1,2
2,1,2,0,0,0,0,0,0,0,0,0,0,0,0,0,2,1,2
2,1,2,10,0,10,0,10,0,10,0,10,0,10,0,10,2,1,2
2,1,2,2,2,2,2,2,2,2,2,2,2,2,2,2,2,1,2
2,1,1,1,1,1,1,1,1,1,1,1,1,1,1,1,1,1,2
2,2,2,2,2,2,2,2,2,2,2,2,2,2,2,2,2,2,2
endlayer

layer
2,2,2,2,2,2,2,2,2,2,2,2,2,2,2,2,2,2,2
2,1,1,1,1,1,1,1,1,1,1,1,1,1,1,1,1,1,2
2,1,2,2,2,2,2,2,2,2,2,2,2,2,2,2,2,1,2
2,1,2,0,0,0,0,0,0,0,0,0,0,0,0,0,2,1,2
2,1,2,0,0,0,0,0,0,0,0,0,0,0,0,0,2,1,2
2,1,2,0,0,0,0,0,0,0,0,0,0,0,0,0,2,1,2
2,1,2,0,0,0,0,0,0,0,0,0,0,0,0,0,2,1,2
2,1,2,0,0,0,0,0,0,0,0,0,0,0,0,0,2,1,2
2,1,2,0,0,0,0,0,0,0,0,0,0,0,0,0,2,1,2
2,1,2,0,0,0,0,0,0,11,0,0,0,0,0,0,2,1,2
2,1,2,0,0,0,0,0,0,0,0,0,0,0,0,0,2,1,2
2,1,2,0,0,0,0,0,0,0,0,0,0,0,0,0,2,1,2
2,1,2,0,0,0,0,0,0,0,0,0,0,0,0,0,2,1,2
2,1,2,0,0,0,0,0,0,0,0,0,0,0,0,0,2,1,2
2,1,2,0,0,0,0,0,0,0,0,0,0,0,0,0,2,1,2
2,1,2,0,0,0,0,0,0,0,0,0,0,0,0,0,2,1,2
2,1,2,2,2,2,2,2,2,2,2,2,2,2,2,2,2,1,2
2,1,1,1,1,1,1,1,1,1,1,1,1,1,1,1,1,1,2
2,2,2,2,2,2,2,2,2,2,2,2,2,2,2,2,2,2,2
endlayer

layer
2,2,2,2,2,2,2,2,2,2,2,2,2,2,2,2,2,2,2
2,1,1,1,1,1,1,1,1,1,1,1,1,1,1,1,1,1,2
2,1,2,2,2,2,2,2,2,2,2,2,2,2,2,2,2,1,2
2,1,2,0,0,0,0,0,0,0,0,0,0,0,0,0,2,1,2
2,1,2,0,0,0,0,0,0,0,0,0,0,0,0,0,2,1,2
2,1,2,0,0,0,0,0,0,0,0,0,0,0,0,0,2,1,2
2,1,2,0,0,0,0,0,0,0,0,0,0,0,0,0,2,1,2
2,1,2,0,0,0,0,0,0,0,0,0,0,0,0,0,2,1,2
2,1,2,0,0,0,0,0,0,0,0,0,0,0,0,0,2,1,2
2,1,2,0,0,0,0,0,0,0,0,0,0,0,0,0,2,1,2
2,1,2,0,0,0,0,0,0,0,0,0,0,0,0,0,2,1,2
2,1,2,0,0,0,0,0,0,0,0,0,0,0,0,0,2,1,2
2,1,2,0,0,0,0,0,0,0,0,0,0,0,0,0,2,1,2
2,1,2,0,0,0,0,0,0,0,0,0,0,0,0,0,2,1,2
2,1,2,0,0,0,0,0,0,0,0,0,0,0,0,0,2,1,2
2,1,2,0,0,0,0,0,0,0,0,0,0,0,0,0,2,1,2
2,1,2,2,2,2,2,2,2,2,2,2,2,2,2,2,2,1,2
2,1,1,1,1,1,1,1,1,1,1,1,1,1,1,1,1,1,2
2,2,2,2,2,2,2,2,2,2,2,2,2,2,2,2,2,2,2
endlayer

# First reduction  - Layers 18-23

layer
2,2,2,2,0,0,2,2,2,2,2,2,2,0,0,2,2,2,2
2,1,1,1,1,1,1,1,1,1,1,1,1,1,1,1,1,1,2
2,1,2,2,2,2,2,2,2,2,2,2,2,2,2,2,2,1,2
2,1,2,0,0,0,0,0,0,0,0,0,0,0,0,0,2,1,2
0,1,2,0,0,0,0,0,0,0,0,0,0,0,0,0,2,1,0
0,1,2,0,0,0,0,0,0,0,0,0,0,0,0,0,2,1,0
2,1,2,0,0,0,0,0,0,0,0,0,0,0,0,0,2,1,2
2,1,2,0,0,0,0,0,0,0,0,0,0,0,0,0,2,1,2
2,1,2,0,0,0,0,0,0,0,0,0,0,0,0,0,2,1,2
2,1,2,0,0,0,0,0,0,0,0,0,0,0,0,0,2,1,2
2,1,2,0,0,0,0,0,0,0,0,0,0,0,0,0,2,1,2
2,1,2,0,0,0,0,0,0,0,0,0,0,0,0,0,2,1,2
2,1,2,0,0,0,0,0,0,0,0,0,0,0,0,0,2,1,2
0,1,2,0,0,0,0,0,0,0,0,0,0,0,0,0,2,1,0
0,1,2,0,0,0,0,0,0,0,0,0,0,0,0,0,2,1,0
2,1,2,0,0,0,0,0,0,0,0,0,0,0,0,0,2,1,2
2,1,2,2,2,2,2,2,2,2,2,2,2,2,2,2,2,1,2
2,1,1,1,1,1,1,1,1,1,1,1,1,1,1,1,1,1,2
2,2,2,2,0,0,2,2,2,2,2,2,2,0,0,2,2,2,2
endlayer

layer
2,2,2,0,0,0,0,2,2,2,2,2,0,0,0,0,2,2,2
2,1,1,1,1,1,1,1,1,1,1,1,1,1,1,1,1,1,2
2,1,2,2,2,2,2,2,2,2,2,2,2,2,2,2,2,1,2
0,1,2,0,0,0,0,0,0,0,0,0,0,0,0,0,2,1,0
0,1,2,0,0,0,0,0,0,0,0,0,0,0,0,0,2,1,0
0,1,2,0,0,0,0,0,0,0,0,0,0,0,0,0,2,1,0
0,1,2,0,0,0,0,0,0,0,0,0,0,0,0,0,2,1,0
2,1,2,0,0,0,0,0,0,0,0,0,0,0,0,0,2,1,2
2,1,2,0,0,0,0,0,0,0,0,0,0,0,0,0,2,1,2
2,1,2,0,0,0,0,0,0,0,0,0,0,0,0,0,2,1,2
2,1,2,0,0,0,0,0,0,0,0,0,0,0,0,0,2,1,2
2,1,2,0,0,0,0,0,0,0,0,0,0,0,0,0,2,1,2
0,1,2,0,0,0,0,0,0,0,0,0,0,0,0,0,2,1,0
0,1,2,0,0,0,0,0,0,0,0,0,0,0,0,0,2,1,0
0,1,2,0,0,0,0,0,0,0,0,0,0,0,0,0,2,1,0
0,1,2,0,0,0,0,0,0,0,0,0,0,0,0,0,2,1,0
2,1,2,2,2,2,2,2,2,2,2,2,2,2,2,2,2,1,2
2,1,1,1,1,1,1,1,1,1,1,1,1,1,1,1,1,1,2
2,2,2,0,0,0,0,2,2,2,2,2,0,0,0,0,2,2,2
endlayer

layer
2,2,0,0,0,0,0,0,2,2,2,0,0,0,0,0,0,2,2
2,1,1,1,1,1,1,1,1,1,1,1,1,1,1,1,1,1,2
0,1,2,2,2,2,2,2,2,2,2,2,2,2,2,2,2,1,0
0,1,2,0,0,0,0,0,0,0,0,0,0,0,0,0,2,1,0
0,1,2,0,0,0,0,0,0,0,0,0,0,0,0,0,2,1,0
0,1,2,0,0,0,0,0,0,0,0,0,0,0,0,0,2,1,0
0,1,2,0,0,0,0,0,0,0,0,0,0,0,0,0,2,1,0
0,1,2,0,0,0,0,0,0,0,0,0,0,0,0,0,2,1,0
2,1,2,0,0,0,0,0,0,0,0,0,0,0,0,0,2,1,2
2,1,2,0,0,0,0,0,0,0,0,0,0,0,0,0,2,1,2
2,1,2,0,0,0,0,0,0,0,0,0,0,0,0,0,2,1,2
0,1,2,0,0,0,0,0,0,0,0,0,0,0,0,0,2,1,0
0,1,2,0,0,0,0,0,0,0,0,0,0,0,0,0,2,1,0
0,1,2,0,0,0,0,0,0,0,0,0,0,0,0,0,2,1,0
0,1,2,0,0,0,0,0,0,0,0,0,0,0,0,0,2,1,0
0,1,2,0,0,0,0,0,0,0,0,0,0,0,0,0,2,1,0
0,1,2,2,2,2,2,2,2,2,2,2,2,2,2,2,2,1,0
2,1,1,1,1,1,1,1,1,1,1,1,1,1,1,1,1,1,2
2,2,0,0,0,0,0,0,2,2,2,0,0,0,0,0,0,2,2
endlayer

layer
2,0,0,0,0,0,0,0,0,2,0,0,0,0,0,0,0,0,2
0,1,1,1,1,1,1,1,1,1,1,1,1,1,1,1,1,1,0
0,1,2,2,2,2,2,2,2,2,2,2,2,2,2,2,2,1,0
0,1,2,0,0,0,0,0,0,0,0,0,0,0,0,0,2,1,0
0,1,2,0,0,0,0,0,0,0,0,0,0,0,0,0,2,1,0
0,1,2,0,0,0,0,0,0,0,0,0,0,0,0,0,2,1,0
0,1,2,0,0,0,0,0,0,0,0,0,0,0,0,0,2,1,0
0,1,2,0,0,0,0,0,0,0,0,0,0,0,0,0,2,1,0
0,1,2,0,0,0,0,0,0,0,0,0,0,0,0,0,2,1,0
2,1,2,0,0,0,0,0,0,0,0,0,0,0,0,0,2,1,2
0,1,2,0,0,0,0,0,0,0,0,0,0,0,0,0,2,1,0
0,1,2,0,0,0,0,0,0,0,0,0,0,0,0,0,2,1,0
0,1,2,0,0,0,0,0,0,0,0,0,0,0,0,0,2,1,0
0,1,2,0,0,0,0,0,0,0,0,0,0,0,0,0,2,1,0
0,1,2,0,0,0,0,0,0,0,0,0,0,0,0,0,2,1,0
0,1,2,0,0,0,0,0,0,0,0,0,0,0,0,0,2,1,0
0,1,2,2,2,2,2,2,2,2,2,2,2,2,2,2,2,1,0
0,1,1,1,1,1,1,1,1,1,1,1,1,1,1,1,1,1,0
2,0,0,0,0,0,0,0,0,2,0,0,0,0,0,0,0,0,2
endlayer

layer
0,0,0,0,0,0,0,0,0,0,0,0,0,0,0,0,0,0,0
0,1,1,1,1,1,1,1,1,1,1,1,1,1,1,1,1,1,0
0,1,2,2,2,2,2,2,2,2,2,2,2,2,2,2,2,1,0
0,1,2,0,0,0,0,0,0,0,0,0,0,0,0,0,2,1,0
0,1,2,0,0,0,0,0,0,0,0,0,0,0,0,0,2,1,0
0,1,2,0,0,0,0,0,0,0,0,0,0,0,0,0,2,1,0
0,1,2,0,0,0,0,0,0,0,0,0,0,0,0,0,2,1,0
0,1,2,0,0,0,0,0,0,0,0,0,0,0,0,0,2,1,0
0,1,2,0,0,0,0,0,0,0,0,0,0,0,0,0,2,1,0
0,1,2,0,0,0,0,0,0,0,0,0,0,0,0,0,2,1,0
0,1,2,0,0,0,0,0,0,0,0,0,0,0,0,0,2,1,0
0,1,2,0,0,0,0,0,0,0,0,0,0,0,0,0,2,1,0
0,1,2,0,0,0,0,0,0,0,0,0,0,0,0,0,2,1,0
0,1,2,0,0,0,0,0,0,0,0,0,0,0,0,0,2,1,0
0,1,2,0,0,0,0,0,0,0,0,0,0,0,0,0,2,1,0
0,1,2,0,0,0,0,0,0,0,0,0,0,0,0,0,2,1,0
0,1,2,2,2,2,2,2,2,2,2,2,2,2,2,2,2,1,0
0,1,1,1,1,1,1,1,1,1,1,1,1,1,1,1,1,1,0
0,0,0,0,0,0,0,0,0,0,0,0,0,0,0,0,0,0,0
endlayer

layer
0,0,0,0,0,0,0,0,0,0,0,0,0,0,0,0,0,0,0
0,1,1,1,1,1,1,1,1,1,1,1,1,1,1,1,1,1,0
0,1,2,2,2,2,2,2,2,2,2,2,2,2,2,2,2,1,0
0,1,2,0,0,0,0,0,0,0,0,0,0,0,0,0,2,1,0
0,1,2,0,0,0,0,0,0,0,0,0,0,0,0,0,2,1,0
0,1,2,0,0,0,0,0,0,0,0,0,0,0,0,0,2,1,0
0,1,2,0,0,0,0,0,0,0,0,0,0,0,0,0,2,1,0
0,1,2,0,0,0,0,0,0,0,0,0,0,0,0,0,2,1,0
0,1,2,0,0,0,0,0,0,0,0,0,0,0,0,0,2,1,0
0,1,2,0,0,0,0,0,0,0,0,0,0,0,0,0,2,1,0
0,1,2,0,0,0,0,0,0,0,0,0,0,0,0,0,2,1,0
0,1,2,0,0,0,0,0,0,0,0,0,0,0,0,0,2,1,0
0,1,2,0,0,0,0,0,0,0,0,0,0,0,0,0,2,1,0
0,1,2,0,0,0,0,0,0,0,0,0,0,0,0,0,2,1,0
0,1,2,0,0,0,0,0,0,0,0,0,0,0,0,0,2,1,0
0,1,2,0,0,0,0,0,0,0,0,0,0,0,0,0,2,1,0
0,1,2,2,2,2,2,2,2,2,2,2,2,2,2,2,2,1,0
0,1,1,1,1,1,1,1,1,1,1,1,1,1,1,1,1,1,0
0,0,0,0,0,0,0,0,0,0,0,0,0,0,0,0,0,0,0
endlayer

# Second Reduction - Layer 24-28

layer
0,0,0,0,0,0,0,0,0,0,0,0,0,0,0,0,0,0,0
0,1,1,1,0,0,0,1,1,1,1,1,0,0,0,1,1,1,0
0,1,2,2,2,2,2,2,2,2,2,2,2,2,2,2,2,1,0
0,1,2,0,0,0,0,0,0,0,0,0,0,0,0,0,2,1,0
0,0,2,0,0,0,0,0,0,0,0,0,0,0,0,0,2,0,0
0,0,2,0,0,0,0,0,0,0,0,0,0,0,0,0,2,0,0
0,0,2,0,0,0,0,0,0,0,0,0,0,0,0,0,2,0,0
0,1,2,0,0,0,0,0,0,0,0,0,0,0,0,0,2,1,0
0,1,2,0,0,0,0,0,0,0,0,0,0,0,0,0,2,1,0
0,1,2,0,0,0,0,0,0,0,0,0,0,0,0,0,2,1,0
0,1,2,0,0,0,0,0,0,0,0,0,0,0,0,0,2,1,0
0,1,2,0,0,0,0,0,0,0,0,0,0,0,0,0,2,1,0
0,0,2,0,0,0,0,0,0,0,0,0,0,0,0,0,2,0,0
0,0,2,0,0,0,0,0,0,0,0,0,0,0,0,0,2,0,0
0,0,2,0,0,0,0,0,0,0,0,0,0,0,0,0,2,0,0
0,1,2,0,0,0,0,0,0,0,0,0,0,0,0,0,2,1,0
0,1,2,2,2,2,2,2,2,2,2,2,2,2,2,2,2,1,0
0,1,1,1,0,0,0,1,1,1,1,1,0,0,0,1,1,1,0
0,0,0,0,0,0,0,0,0,0,0,0,0,0,0,0,0,0,0
endlayer

layer
0,0,0,0,0,0,0,0,0,0,0,0,0,0,0,0,0,0,0
0,1,1,0,0,0,0,0,1,1,1,0,0,0,0,0,1,1,0
0,1,2,2,2,2,2,2,2,2,2,2,2,2,2,2,2,1,0
0,0,2,0,0,0,0,0,0,0,0,0,0,0,0,0,2,0,0
0,0,2,0,0,0,0,0,0,0,0,0,0,0,0,0,2,0,0
0,0,2,0,0,0,0,0,0,0,0,0,0,0,0,0,2,0,0
0,0,2,0,0,0,0,0,0,0,0,0,0,0,0,0,2,0,0
0,0,2,0,0,0,0,0,0,0,0,0,0,0,0,0,2,0,0
0,1,2,0,0,0,0,0,0,0,0,0,0,0,0,0,2,1,0
0,1,2,0,0,0,0,0,0,0,0,0,0,0,0,0,2,1,0
0,1,2,0,0,0,0,0,0,0,0,0,0,0,0,0,2,1,0
0,0,2,0,0,0,0,0,0,0,0,0,0,0,0,0,2,0,0
0,0,2,0,0,0,0,0,0,0,0,0,0,0,0,0,2,0,0
0,0,2,0,0,0,0,0,0,0,0,0,0,0,0,0,2,0,0
0,0,2,0,0,0,0,0,0,0,0,0,0,0,0,0,2,0,0
0,0,2,0,0,0,0,0,0,0,0,0,0,0,0,0,2,0,0
0,1,2,2,2,2,2,2,2,2,2,2,2,2,2,2,2,1,0
0,1,1,0,0,0,0,0,1,1,1,0,0,0,0,0,1,1,0
0,0,0,0,0,0,0,0,0,0,0,0,0,0,0,0,0,0,0
endlayer

layer
0,0,0,0,0,0,0,0,0,0,0,0,0,0,0,0,0,0,0
0,1,0,0,0,0,0,0,0,1,0,0,0,0,0,0,0,1,0
0,0,2,2,2,2,2,2,2,2,2,2,2,2,2,2,2,0,0
0,0,2,0,0,0,0,0,0,0,0,0,0,0,0,0,2,0,0
0,0,2,0,0,0,0,0,0,0,0,0,0,0,0,0,2,0,0
0,0,2,0,0,0,0,0,0,0,0,0,0,0,0,0,2,0,0
0,0,2,0,0,0,0,0,0,0,0,0,0,0,0,0,2,0,0
0,0,2,0,0,0,0,0,0,0,0,0,0,0,0,0,2,0,0
0,0,2,0,0,0,0,0,0,0,0,0,0,0,0,0,2,0,0
0,1,2,0,0,0,0,0,0,0,0,0,0,0,0,0,2,1,0
0,0,2,0,0,0,0,0,0,0,0,0,0,0,0,0,2,0,0
0,0,2,0,0,0,0,0,0,0,0,0,0,0,0,0,2,0,0
0,0,2,0,0,0,0,0,0,0,0,0,0,0,0,0,2,0,0
0,0,2,0,0,0,0,0,0,0,0,0,0,0,0,0,2,0,0
0,0,2,0,0,0,0,0,0,0,0,0,0,0,0,0,2,0,0
0,0,2,0,0,0,0,0,0,0,0,0,0,0,0,0,2,0,0
0,0,2,2,2,2,2,2,2,2,2,2,2,2,2,2,2,0,0
0,1,0,0,0,0,0,0,0,1,0,0,0,0,0,0,0,1,0
0,0,0,0,0,0,0,0,0,0,0,0,0,0,0,0,0,0,0
endlayer

layer
0,0,0,0,0,0,0,0,0,0,0,0,0,0,0,0,0,0,0
0,0,0,0,0,0,0,0,0,0,0,0,0,0,0,0,0,0,0
0,0,2,2,2,2,2,2,2,2,2,2,2,2,2,2,2,0,0
0,0,2,0,0,0,0,0,0,0,0,0,0,0,0,0,2,0,0
0,0,2,0,0,0,0,0,0,0,0,0,0,0,0,0,2,0,0
0,0,2,0,0,0,0,0,0,0,0,0,0,0,0,0,2,0,0
0,0,2,0,0,0,0,0,0,0,0,0,0,0,0,0,2,0,0
0,0,2,0,0,0,0,0,0,0,0,0,0,0,0,0,2,0,0
0,0,2,0,0,0,0,0,0,0,0,0,0,0,0,0,2,0,0
0,0,2,0,0,0,0,0,0,0,0,0,0,0,0,0,2,0,0
0,0,2,0,0,0,0,0,0,0,0,0,0,0,0,0,2,0,0
0,0,2,0,0,0,0,0,0,0,0,0,0,0,0,0,2,0,0
0,0,2,0,0,0,0,0,0,0,0,0,0,0,0,0,2,0,0
0,0,2,0,0,0,0,0,0,0,0,0,0,0,0,0,2,0,0
0,0,2,0,0,0,0,0,0,0,0,0,0,0,0,0,2,0,0
0,0,2,0,0,0,0,0,0,0,0,0,0,0,0,0,2,0,0
0,0,2,2,2,2,2,2,2,2,2,2,2,2,2,2,2,0,0
0,0,0,0,0,0,0,0,0,0,0,0,0,0,0,0,0,0,0
0,0,0,0,0,0,0,0,0,0,0,0,0,0,0,0,0,0,0
endlayer

layer
0,0,0,0,0,0,0,0,0,0,0,0,0,0,0,0,0,0,0
0,0,0,0,0,0,0,0,0,0,0,0,0,0,0,0,0,0,0
0,0,2,2,2,2,2,2,2,2,2,2,2,2,2,2,2,0,0
0,0,2,0,0,0,0,0,0,0,0,0,0,0,0,0,2,0,0
0,0,2,0,0,0,0,0,0,0,0,0,0,0,0,0,2,0,0
0,0,2,0,0,0,0,0,0,0,0,0,0,0,0,0,2,0,0
0,0,2,0,0,0,0,0,0,0,0,0,0,0,0,0,2,0,0
0,0,2,0,0,0,0,0,0,0,0,0,0,0,0,0,2,0,0
0,0,2,0,0,0,0,0,0,0,0,0,0,0,0,0,2,0,0
0,0,2,0,0,0,0,0,0,0,0,0,0,0,0,0,2,0,0
0,0,2,0,0,0,0,0,0,0,0,0,0,0,0,0,2,0,0
0,0,2,0,0,0,0,0,0,0,0,0,0,0,0,0,2,0,0
0,0,2,0,0,0,0,0,0,0,0,0,0,0,0,0,2,0,0
0,0,2,0,0,0,0,0,0,0,0,0,0,0,0,0,2,0,0
0,0,2,0,0,0,0,0,0,0,0,0,0,0,0,0,2,0,0
0,0,2,0,0,0,0,0,0,0,0,0,0,0,0,0,2,0,0
0,0,2,2,2,2,2,2,2,2,2,2,2,2,2,2,2,0,0
0,0,0,0,0,0,0,0,0,0,0,0,0,0,0,0,0,0,0
0,0,0,0,0,0,0,0,0,0,0,0,0,0,0,0,0,0,0
endlayer

# Capstone - 29-35

layer
0,0,0,0,0,0,0,0,0,0,0,0,0,0,0,0,0,0,0
0,0,0,0,0,0,0,0,0,0,0,0,0,0,0,0,0,0,0
0,0,2,2,2,0,0,2,2,2,2,2,0,0,2,2,2,0,0
0,0,2,1,1,1,1,1,1,1,1,1,1,1,1,1,2,0,0
0,0,2,1,1,1,1,1,1,1,1,1,1,1,1,1,2,0,0
0,0,0,1,1,0,0,0,0,0,0,0,0,0,1,1,0,0,0
0,0,0,1,1,0,0,0,0,0,0,0,0,0,1,1,0,0,0
0,0,2,1,1,0,0,0,0,0,0,0,0,0,1,1,2,0,0
0,0,2,1,1,0,0,0,0,0,0,0,0,0,1,1,2,0,0
0,0,2,1,1,0,0,0,0,0,0,0,0,0,1,1,2,0,0
0,0,2,1,1,0,0,0,0,0,0,0,0,0,1,1,2,0,0
0,0,2,1,1,0,0,0,0,0,0,0,0,0,1,1,2,0,0
0,0,0,1,1,0,0,0,0,0,0,0,0,0,1,1,0,0,0
0,0,0,1,1,0,0,0,0,0,0,0,0,0,1,1,0,0,0
0,0,2,1,1,1,1,1,1,1,1,1,1,1,1,1,2,0,0
0,0,2,1,1,1,1,1,1,1,1,1,1,1,1,1,2,0,0
0,0,2,2,2,0,0,2,2,2,2,2,0,0,2,2,2,0,0
0,0,0,0,0,0,0,0,0,0,0,0,0,0,0,0,0,0,0
0,0,0,0,0,0,0,0,0,0,0,0,0,0,0,0,0,0,0
endlayer

layer
0,0,0,0,0,0,0,0,0,0,0,0,0,0,0,0,0,0,0
0,0,0,0,0,0,0,0,0,0,0,0,0,0,0,0,0,0,0
0,0,2,2,0,0,0,0,2,2,2,0,0,0,0,2,2,0,0
0,0,2,0,0,0,0,0,0,0,0,0,0,0,0,0,2,0,0
0,0,0,0,1,1,1,1,1,1,1,1,1,1,1,0,0,0,0
0,0,0,0,1,1,1,1,1,1,1,1,1,1,1,0,0,0,0
0,0,0,0,1,1,0,0,0,0,0,0,0,1,1,0,0,0,0
0,0,0,0,1,1,0,0,0,0,0,0,0,1,1,0,0,0,0
0,0,2,0,1,1,0,0,0,0,0,0,0,1,1,0,2,0,0
0,0,2,0,1,1,0,0,0,0,0,0,0,1,1,0,2,0,0
0,0,2,0,1,1,0,0,0,0,0,0,0,1,1,0,2,0,0
0,0,0,0,1,1,0,0,0,0,0,0,0,1,1,0,0,0,0
0,0,0,0,1,1,0,0,0,0,0,0,0,1,1,0,0,0,0
0,0,0,0,1,1,1,1,1,1,1,1,1,1,1,0,0,0,0
0,0,0,0,1,1,1,1,1,1,1,1,1,1,1,0,0,0,0
0,0,2,0,0,0,0,0,0,0,0,0,0,0,0,0,2,0,0
0,0,2,2,0,0,0,0,2,2,2,0,0,0,0,2,2,0,0
0,0,0,0,0,0,0,0,0,0,0,0,0,0,0,0,0,0,0
0,0,0,0,0,0,0,0,0,0,0,0,0,0,0,0,0,0,0
endlayer

layer
0,0,0,0,0,0,0,0,0,0,0,0,0,0,0,0,0,0,0
0,0,0,0,0,0,0,0,0,0,0,0,0,0,0,0,0,0,0
0,0,2,0,0,0,0,0,0,2,0,0,0,0,0,0,2,0,0
0,0,0,0,0,0,0,0,0,0,0,0,0,0,0,0,0,0,0
0,0,0,0,0,0,0,0,0,0,0,0,0,0,0,0,0,0,0
0,0,0,0,0,1,1,1,1,1,1,1,1,1,0,0,0,0,0
0,0,0,0,0,1,1,1,1,1,1,1,1,1,0,0,0,0,0
0,0,0,0,0,1,1,0,0,0,0,0,1,1,0,0,0,0,0
0,0,0,0,0,1,1,0,0,0,0,0,1,1,0,0,0,0,0
0,0,2,0,0,1,1,0,0,0,0,0,1,1,0,0,2,0,0
0,0,0,0,0,1,1,0,0,0,0,0,1,1,0,0,0,0,0
0,0,0,0,0,1,1,0,0,0,0,0,1,1,0,0,0,0,0
0,0,0,0,0,1,1,1,1,1,1,1,1,1,0,0,0,0,0
0,0,0,0,0,1,1,1,1,1,1,1,1,1,0,0,0,0,0
0,0,0,0,0,0,0,0,0,0,0,0,0,0,0,0,0,0,0
0,0,0,0,0,0,0,0,0,0,0,0,0,0,0,0,0,0,0
0,0,2,0,0,0,0,0,0,2,0,0,0,0,0,0,2,0,0
0,0,0,0,0,0,0,0,0,0,0,0,0,0,0,0,0,0,0
0,0,0,0,0,0,0,0,0,0,0,0,0,0,0,0,0,0,0
endlayer

layer
0,0,0,0,0,0,0,0,0,0,0,0,0,0,0,0,0,0,0
0,0,0,0,0,0,0,0,0,0,0,0,0,0,0,0,0,0,0
0,0,0,0,0,0,0,0,0,0,0,0,0,0,0,0,0,0,0
0,0,0,0,0,0,0,0,0,0,0,0,0,0,0,0,0,0,0
0,0,0,0,0,0,0,0,0,0,0,0,0,0,0,0,0,0,0
0,0,0,0,0,0,0,0,0,0,0,0,0,0,0,0,0,0,0
0,0,0,0,0,0,1,1,1,1,1,1,1,0,0,0,0,0,0
0,0,0,0,0,0,1,1,1,1,1,1,1,0,0,0,0,0,0
0,0,0,0,0,0,1,1,0,0,0,1,1,0,0,0,0,0,0
0,0,0,0,0,0,1,1,0,0,0,1,1,0,0,0,0,0,0
0,0,0,0,0,0,1,1,0,0,0,1,1,0,0,0,0,0,0
0,0,0,0,0,0,1,1,1,1,1,1,1,0,0,0,0,0,0
0,0,0,0,0,0,1,1,1,1,1,1,1,0,0,0,0,0,0
0,0,0,0,0,0,0,0,0,0,0,0,0,0,0,0,0,0,0
0,0,0,0,0,0,0,0,0,0,0,0,0,0,0,0,0,0,0
0,0,0,0,0,0,0,0,0,0,0,0,0,0,0,0,0,0,0
0,0,0,0,0,0,0,0,0,0,0,0,0,0,0,0,0,0,0
0,0,0,0,0,0,0,0,0,0,0,0,0,0,0,0,0,0,0
0,0,0,0,0,0,0,0,0,0,0,0,0,0,0,0,0,0,0
endlayer

layer
0,0,0,0,0,0,0,0,0,0,0,0,0,0,0,0,0,0,0
0,0,0,0,0,0,0,0,0,0,0,0,0,0,0,0,0,0,0
0,0,0,0,0,0,0,0,0,0,0,0,0,0,0,0,0,0,0
0,0,0,0,0,0,0,0,0,0,0,0,0,0,0,0,0,0,0
0,0,0,0,0,0,0,0,0,0,0,0,0,0,0,0,0,0,0
0,0,0,0,0,0,0,0,0,0,0,0,0,0,0,0,0,0,0
0,0,0,0,0,0,0,0,0,0,0,0,0,0,0,0,0,0,0
0,0,0,0,0,0,0,1,1,1,1,1,0,0,0,0,0,0,0
0,0,0,0,0,0,0,1,1,1,1,1,0,0,0,0,0,0,0
0,0,0,0,0,0,0,1,1,0,1,1,0,0,0,0,0,0,0
0,0,0,0,0,0,0,1,1,1,1,1,0,0,0,0,0,0,0
0,0,0,0,0,0,0,1,1,1,1,1,0,0,0,0,0,0,0
0,0,0,0,0,0,0,0,0,0,0,0,0,0,0,0,0,0,0
0,0,0,0,0,0,0,0,0,0,0,0,0,0,0,0,0,0,0
0,0,0,0,0,0,0,0,0,0,0,0,0,0,0,0,0,0,0
0,0,0,0,0,0,0,0,0,0,0,0,0,0,0,0,0,0,0
0,0,0,0,0,0,0,0,0,0,0,0,0,0,0,0,0,0,0
0,0,0,0,0,0,0,0,0,0,0,0,0,0,0,0,0,0,0
0,0,0,0,0,0,0,0,0,0,0,0,0,0,0,0,0,0,0
endlayer

layer
0,0,0,0,0,0,0,0,0,0,0,0,0,0,0,0,0,0,0
0,0,0,0,0,0,0,0,0,0,0,0,0,0,0,0,0,0,0
0,0,0,0,0,0,0,0,0,0,0,0,0,0,0,0,0,0,0
0,0,0,0,0,0,0,0,0,0,0,0,0,0,0,0,0,0,0
0,0,0,0,0,0,0,0,0,0,0,0,0,0,0,0,0,0,0
0,0,0,0,0,0,0,0,0,0,0,0,0,0,0,0,0,0,0
0,0,0,0,0,0,0,0,0,0,0,0,0,0,0,0,0,0,0
0,0,0,0,0,0,0,0,0,0,0,0,0,0,0,0,0,0,0
0,0,0,0,0,0,0,0,1,1,1,0,0,0,0,0,0,0,0
0,0,0,0,0,0,0,0,1,1,1,0,0,0,0,0,0,0,0
0,0,0,0,0,0,0,0,1,1,1,0,0,0,0,0,0,0,0
0,0,0,0,0,0,0,0,0,0,0,0,0,0,0,0,0,0,0
0,0,0,0,0,0,0,0,0,0,0,0,0,0,0,0,0,0,0
0,0,0,0,0,0,0,0,0,0,0,0,0,0,0,0,0,0,0
0,0,0,0,0,0,0,0,0,0,0,0,0,0,0,0,0,0,0
0,0,0,0,0,0,0,0,0,0,0,0,0,0,0,0,0,0,0
0,0,0,0,0,0,0,0,0,0,0,0,0,0,0,0,0,0,0
0,0,0,0,0,0,0,0,0,0,0,0,0,0,0,0,0,0,0
0,0,0,0,0,0,0,0,0,0,0,0,0,0,0,0,0,0,0
endlayer

layer
0,0,0,0,0,0,0,0,0,0,0,0,0,0,0,0,0,0,0
0,0,0,0,0,0,0,0,0,0,0,0,0,0,0,0,0,0,0
0,0,0,0,0,0,0,0,0,0,0,0,0,0,0,0,0,0,0
0,0,0,0,0,0,0,0,0,0,0,0,0,0,0,0,0,0,0
0,0,0,0,0,0,0,0,0,0,0,0,0,0,0,0,0,0,0
0,0,0,0,0,0,0,0,0,0,0,0,0,0,0,0,0,0,0
0,0,0,0,0,0,0,0,0,0,0,0,0,0,0,0,0,0,0
0,0,0,0,0,0,0,0,0,0,0,0,0,0,0,0,0,0,0
0,0,0,0,0,0,0,0,0,0,0,0,0,0,0,0,0,0,0
0,0,0,0,0,0,0,0,0,1,0,0,0,0,0,0,0,0,0
0,0,0,0,0,0,0,0,0,0,0,0,0,0,0,0,0,0,0
0,0,0,0,0,0,0,0,0,0,0,0,0,0,0,0,0,0,0
0,0,0,0,0,0,0,0,0,0,0,0,0,0,0,0,0,0,0
0,0,0,0,0,0,0,0,0,0,0,0,0,0,0,0,0,0,0
0,0,0,0,0,0,0,0,0,0,0,0,0,0,0,0,0,0,0
0,0,0,0,0,0,0,0,0,0,0,0,0,0,0,0,0,0,0
0,0,0,0,0,0,0,0,0,0,0,0,0,0,0,0,0,0,0
0,0,0,0,0,0,0,0,0,0,0,0,0,0,0,0,0,0,0
0,0,0,0,0,0,0,0,0,0,0,0,0,0,0,0,0,0,0
endlayer