#BASICS


weight=7
embed_into_distance=22
acceptable_target_blocks=1,2,3,9,12,13,49,79,110
dimensions=25,7,7
allowable_overhang=10
max_cut_in=5
cut_in_buffer=1
max_leveling=2
leveling_buffer=1
preserve_water=0
preserve_lava=0
preserve_plants=0


#RULES LIST - SETS BLOCK NUMBERS

rule1=0,100,9
rule2=0,100,3
rule3=0,100,17
rule4=0,100,24
rule5=0,100,83
rule6=0,100,85
rule7=0,100,300

#MY LIST OF BLOCKS

#     0 = AIR
#     1 = Water
#     2 = Dirt
#     3 = Log
#     4 = Sandstone
#     5 = Sugarcane
#     6 = Fencepost
#     7 = LEAVE

# No change - 20 layers

layer
7,7,7,7,7,7,7
7,7,7,7,7,7,7
7,7,7,7,7,7,7
7,7,7,7,7,7,7
7,7,7,7,7,7,7
7,7,7,7,7,7,7
7,7,7,7,7,7,7
endlayer

layer
7,7,7,7,7,7,7
7,7,7,7,7,7,7
7,7,7,7,7,7,7
7,7,7,7,7,7,7
7,7,7,7,7,7,7
7,7,7,7,7,7,7
7,7,7,7,7,7,7
endlayer

layer
7,7,7,7,7,7,7
7,7,7,7,7,7,7
7,7,7,7,7,7,7
7,7,7,7,7,7,7
7,7,7,7,7,7,7
7,7,7,7,7,7,7
7,7,7,7,7,7,7
endlayer

layer
7,7,7,7,7,7,7
7,7,7,7,7,7,7
7,7,7,7,7,7,7
7,7,7,7,7,7,7
7,7,7,7,7,7,7
7,7,7,7,7,7,7
7,7,7,7,7,7,7
endlayer

layer
7,7,7,7,7,7,7
7,7,7,7,7,7,7
7,7,7,7,7,7,7
7,7,7,7,7,7,7
7,7,7,7,7,7,7
7,7,7,7,7,7,7
7,7,7,7,7,7,7
endlayer

layer
7,7,7,7,7,7,7
7,7,7,7,7,7,7
7,7,7,7,7,7,7
7,7,7,7,7,7,7
7,7,7,7,7,7,7
7,7,7,7,7,7,7
7,7,7,7,7,7,7
endlayer

layer
7,7,7,7,7,7,7
7,7,7,7,7,7,7
7,7,7,7,7,7,7
7,7,7,7,7,7,7
7,7,7,7,7,7,7
7,7,7,7,7,7,7
7,7,7,7,7,7,7
endlayer

layer
7,7,7,7,7,7,7
7,7,7,7,7,7,7
7,7,7,7,7,7,7
7,7,7,7,7,7,7
7,7,7,7,7,7,7
7,7,7,7,7,7,7
7,7,7,7,7,7,7
endlayer

layer
7,7,7,7,7,7,7
7,7,7,7,7,7,7
7,7,7,7,7,7,7
7,7,7,7,7,7,7
7,7,7,7,7,7,7
7,7,7,7,7,7,7
7,7,7,7,7,7,7
endlayer

layer
7,7,7,7,7,7,7
7,7,7,7,7,7,7
7,7,7,7,7,7,7
7,7,7,7,7,7,7
7,7,7,7,7,7,7
7,7,7,7,7,7,7
7,7,7,7,7,7,7
endlayer

layer
7,7,7,7,7,7,7
7,7,7,7,7,7,7
7,7,7,7,7,7,7
7,7,7,7,7,7,7
7,7,7,7,7,7,7
7,7,7,7,7,7,7
7,7,7,7,7,7,7
endlayer

layer
7,7,7,7,7,7,7
7,7,7,7,7,7,7
7,7,7,7,7,7,7
7,7,7,7,7,7,7
7,7,7,7,7,7,7
7,7,7,7,7,7,7
7,7,7,7,7,7,7
endlayer

layer
7,7,7,7,7,7,7
7,7,7,7,7,7,7
7,7,7,7,7,7,7
7,7,7,7,7,7,7
7,7,7,7,7,7,7
7,7,7,7,7,7,7
7,7,7,7,7,7,7
endlayer

layer
7,7,7,7,7,7,7
7,7,7,7,7,7,7
7,7,7,7,7,7,7
7,7,7,7,7,7,7
7,7,7,7,7,7,7
7,7,7,7,7,7,7
7,7,7,7,7,7,7
endlayer

layer
7,7,7,7,7,7,7
7,7,7,7,7,7,7
7,7,7,7,7,7,7
7,7,7,7,7,7,7
7,7,7,7,7,7,7
7,7,7,7,7,7,7
7,7,7,7,7,7,7
endlayer

layer
7,7,7,7,7,7,7
7,7,7,7,7,7,7
7,7,7,7,7,7,7
7,7,7,7,7,7,7
7,7,7,7,7,7,7
7,7,7,7,7,7,7
7,7,7,7,7,7,7
endlayer

layer
7,7,7,7,7,7,7
7,7,7,7,7,7,7
7,7,7,7,7,7,7
7,7,7,7,7,7,7
7,7,7,7,7,7,7
7,7,7,7,7,7,7
7,7,7,7,7,7,7
endlayer

layer
7,7,7,7,7,7,7
7,7,7,7,7,7,7
7,7,7,7,7,7,7
7,7,7,7,7,7,7
7,7,7,7,7,7,7
7,7,7,7,7,7,7
7,7,7,7,7,7,7
endlayer

layer
7,7,7,7,7,7,7
7,7,7,7,7,7,7
7,7,7,7,7,7,7
7,7,7,7,7,7,7
7,7,7,7,7,7,7
7,7,7,7,7,7,7
7,7,7,7,7,7,7
endlayer

layer
7,7,7,7,7,7,7
7,7,7,7,7,7,7
7,7,7,7,7,7,7
7,7,7,7,7,7,7
7,7,7,7,7,7,7
7,7,7,7,7,7,7
7,7,7,7,7,7,7
endlayer


#Foundation - 5 layers

layer
4,4,4,4,4,4,4
4,4,4,4,4,4,4
4,4,4,4,4,4,4
4,4,4,4,4,4,4
4,4,4,4,4,4,4
4,4,4,4,4,4,4
4,4,4,4,4,4,4
endlayer

#Up

layer
4,4,4,4,4,4,4
4,2,1,2,1,2,4
4,2,1,2,1,2,4
4,2,1,2,1,2,4
4,2,1,2,1,2,4
4,2,1,2,1,2,4
4,4,4,4,4,4,4
endlayer

layer
4,4,4,4,4,4,4
4,5,0,5,0,5,4
4,5,0,5,0,5,4
0,5,0,5,0,5,4
4,5,0,5,0,5,4
4,5,0,5,0,5,4
4,4,4,4,4,4,4
endlayer

layer
6,6,6,6,6,6,6
6,5,0,5,0,5,6
6,5,0,5,0,5,6
0,5,0,5,0,5,6
6,5,0,5,0,5,6
6,5,0,5,0,5,6
6,6,6,6,6,6,6
endlayer

layer
0,0,0,0,0,0,0
0,5,0,5,0,5,0
0,5,0,5,0,5,0
0,5,0,5,0,5,0
0,5,0,5,0,5,0
0,5,0,5,0,5,0
0,0,0,0,0,0,0
endlayer