# Ankh Monument (intact)
# MC 1.7.10; 2 Nov 2014
# Created by Ruins mod version 14.1 Ingame Parser
# authoring Player: Jordan_Greywolf
# Verified for MC 1.11: 10 Jan 2017

biomesToSpawnIn=desert,deserthills,desert m,lush desert,oasis,dunes,desert oil field,rwg_hotdesert

weight=1
embed_into_distance=4
acceptable_target_blocks=

unacceptable_target_blocks=flowing_water,water,flowing_lava,lava,cloud,Natura:Cloud

dimensions=17,5,5
allowable_overhang=0
max_leveling=4
leveling_buffer=-1
preserve_water=0
preserve_lava=0
preserve_plants=1

rule1=0,100,minecraft:sandstone_stairs-0
rule2=0,100,minecraft:sandstone_stairs-3
rule3=0,100,minecraft:sandstone_stairs-2
rule4=0,100,minecraft:sandstone-0
rule5=0,100,minecraft:sandstone_stairs-1
rule6=0,100,minecraft:sandstone-2
rule7=0,100,minecraft:sandstone-1
rule8=0,100,minecraft:sandstone_stairs-4
rule9=0,100,minecraft:sandstone_stairs-7
rule10=0,100,minecraft:sandstone_stairs-6
rule11=0,100,minecraft:sandstone_stairs-5

layer
4,4,4,4,4
4,4,4,4,4
4,4,4,4,4
4,4,4,4,4
4,4,4,4,4
endlayer

layer
4,4,4,4,4
4,4,4,4,4
4,4,4,4,4
4,4,4,4,4
4,4,4,4,4
endlayer

layer
4,4,4,4,4
4,4,4,4,4
4,4,4,4,4
4,4,4,4,4
4,4,4,4,4
endlayer

layer
4,4,4,4,4
4,4,4,4,4
4,4,4,4,4
4,4,4,4,4
4,4,4,4,4
endlayer




layer
2,1,1,1,1
2,4,4,4,3
2,4,4,4,3
2,4,4,4,3
5,5,5,5,3
endlayer

layer
0,0,0,0,0
0,6,6,6,0
0,6,6,6,0
0,6,6,6,0
0,0,0,0,0
endlayer

layer
0,0,0,0,0
0,7,7,7,0
0,7,7,7,0
0,7,7,7,0
0,0,0,0,0
endlayer

layer
0,0,0,0,0
0,6,6,6,0
0,6,6,6,0
0,6,6,6,0
0,0,0,0,0
endlayer

layer
9,8,8,8,8
9,4,4,4,10
9,4,4,4,10
9,4,4,4,10
11,11,11,11,10
endlayer

layer
0,0,0,0,0
0,0,0,0,0
0,6,6,6,0
0,0,0,0,0
0,0,0,0,0
endlayer

layer
0,0,0,0,0
0,0,0,0,0
0,0,6,0,0
0,0,0,0,0
0,0,0,0,0
endlayer

layer
0,0,0,0,0
0,0,0,0,0
0,0,6,0,0
0,0,0,0,0
0,0,0,0,0
endlayer

layer
0,0,0,0,0
0,0,0,0,0
0,6,6,6,0
0,0,0,0,0
0,0,0,0,0
endlayer

layer
0,0,0,0,0
0,0,0,0,0
0,0,6,0,0
0,0,0,0,0
0,0,0,0,0
endlayer

layer
0,0,0,0,0
0,0,0,0,0
0,6,0,6,0
0,0,0,0,0
0,0,0,0,0
endlayer

layer
0,0,0,0,0
0,0,0,0,0
0,6,0,6,0
0,0,0,0,0
0,0,0,0,0
endlayer

layer
0,0,0,0,0
0,0,0,0,0
0,0,6,0,0
0,0,0,0,0
0,0,0,0,0
endlayer

