#BASICS


weight=12
embed_into_distance=0
acceptable_target_blocks=1,2,3,12,13,49,79,110
dimensions=6,19,19
max_cut_in=5
cut_in_buffer=1
max_leveling=2
leveling_buffer=1
preserve_water=0
preserve_lava=0
preserve_plants=0


#RULES LIST - SETS BLOCK NUMBERS

rule1=0,100,49
rule2=0,100,24
rule3=0,100,65-0
rule4=0,100,5
rule5=0,100,85
rule6=0,100,12
rule7=0,100,44-2
rule8=0,100,37
rule9=0,100,40
rule10=0,100,89
rule11=0,100,25

#MY LIST OF BLOCKS

#     0 = AIR
#     1 = Obsidian
#     2 = Sandstone
#     3 = Ladder-0
#     4 = Planks
#     5 = Fencepost
#     6 = sand
#     7 = Half-plank
#     8 = Yellow Flower
#     9 = Red Mushroom
#     10 = Glowstone
#     11 = Note Block

#     300 = Leave existing world block alone
#     301 = Mob Spawner (Zombie)
#     302 = Mob Spawner (Skeleton) 
#     303 = Mob Spawner (Spider)
#     304 = Mob Spawner (Creeper)
#     305 = Mob Spawner (Zombie, Skeleton, Creeper)
#     306 = Mob Spawner (Easy, zombies and skeletons)
#     307 = Mob Spawner (Medium, zombies, skeletons, and spiders)
#     308 = Mob Spawner (Hard, all mobs)
#     309 = Easy Chest (For Easy rewards)
#     310 = Medium Chest (For Medium rewards)
#     311 = Hard Chest (For Hard rewards)


# LAYERS
# Each layer is a comma-delimited list of rules, one for each block.  There
# must be as many layers as the height, and each layer must have "layer" before
# the rules and end with "endlayer".  There are as many rows as the length, and
# as many rules as the width.  If you want the block blanked out use 0, which
# represents the Air-block rule.


#Foundation

layer
2,2,2,2,2,2,2,2,2,2,2,2,2,2,2,2,2,2,2
2,4,4,4,4,4,4,4,4,4,4,2,4,4,4,4,4,4,2
2,4,4,4,4,4,4,4,4,4,4,2,4,4,4,4,4,4,2
2,4,4,4,4,4,4,4,4,4,4,2,4,4,4,4,4,4,2
2,4,4,4,4,4,4,4,4,4,4,2,4,4,4,4,4,4,2
2,4,4,4,4,4,4,4,4,4,4,2,4,4,4,4,4,4,2
2,2,2,2,2,2,2,4,4,2,2,2,4,4,4,4,4,4,2
2,6,6,6,6,6,6,4,4,6,6,2,4,4,4,4,4,4,2
2,6,4,4,4,4,4,4,4,6,6,2,4,4,4,4,4,4,2
2,6,4,4,4,4,4,4,4,6,6,2,4,4,4,4,4,4,2
2,6,4,4,4,4,4,4,4,6,6,2,4,4,4,4,4,4,2
2,6,6,4,6,6,6,4,4,6,6,2,4,4,4,4,4,4,2
2,2,2,4,2,2,6,4,4,6,6,2,4,4,4,4,4,4,2
2,4,4,4,4,2,6,4,4,6,6,2,4,4,4,4,4,4,2
2,4,4,4,4,2,6,4,4,6,6,2,4,4,4,4,4,4,2
2,4,4,4,4,2,6,4,4,6,6,2,4,4,4,4,4,4,2
2,4,4,4,4,2,6,4,4,6,6,2,4,4,4,4,4,4,2
2,4,4,4,4,2,6,4,4,6,6,2,4,4,4,4,4,4,2
2,2,2,2,2,2,2,2,2,2,2,2,2,2,2,2,2,2,2
endlayer


layer
2,2,2,2,2,2,2,2,2,2,2,2,2,2,2,2,2,2,2
2,0,0,0,0,0,0,0,0,0,0,2,0,0,0,0,0,0,2
2,0,0,0,0,0,0,0,0,0,0,2,0,0,0,0,0,0,2
2,0,0,0,0,0,0,0,0,0,0,0,0,0,0,0,0,0,2
2,0,0,0,0,0,0,0,0,0,0,0,0,0,0,0,0,0,2
2,0,0,0,0,0,0,0,0,0,0,2,0,0,0,0,0,0,2
2,2,2,2,2,2,2,0,0,2,2,2,0,0,0,0,0,0,2
2,0,0,0,0,0,0,0,0,0,0,2,0,0,0,0,0,0,2
2,0,0,0,0,0,0,0,0,0,0,2,0,0,0,0,0,0,2
2,0,0,0,0,0,0,0,0,0,0,2,0,0,0,0,0,0,2
2,0,0,0,0,0,0,0,0,0,0,2,0,0,0,0,0,0,2
2,0,0,0,0,0,0,0,0,0,0,2,0,0,0,0,0,0,2
2,2,2,0,2,2,0,0,0,0,0,2,0,0,0,0,0,0,2
2,0,0,0,0,2,0,0,0,0,0,2,2,2,2,2,0,0,2
2,0,0,0,0,2,0,0,0,0,0,2,4,4,2,2,0,0,2
2,0,0,0,0,2,0,0,0,0,0,2,4,4,2,2,7,7,2
2,0,0,0,0,2,0,0,0,0,0,2,4,4,4,4,4,4,2
2,0,0,0,0,2,2,0,0,2,2,2,4,4,4,4,4,4,2
2,2,2,2,2,2,0,0,0,0,0,2,2,2,2,2,2,2,2
endlayer

layer
2,2,2,2,2,2,2,2,2,2,2,2,2,2,2,2,2,2,2
2,0,0,0,0,0,0,0,0,0,0,2,0,0,0,0,0,0,2
2,0,0,0,0,0,0,0,0,0,0,2,0,0,0,0,0,0,2
2,0,0,0,0,0,0,0,0,0,0,0,0,0,0,0,0,0,2
2,0,0,0,0,0,0,0,0,0,0,0,0,0,0,0,0,0,2
2,0,0,0,0,0,0,0,0,0,0,2,0,0,0,0,0,0,2
2,2,2,2,2,2,2,0,0,2,2,2,0,0,0,0,0,0,2
5,0,0,0,0,0,0,0,0,0,0,2,0,0,0,0,0,0,2
5,0,0,0,0,0,0,0,0,0,0,2,0,0,0,0,0,0,2
5,0,0,0,0,0,0,0,0,0,0,2,0,0,0,0,0,0,2
5,0,0,0,0,0,0,0,0,0,0,2,0,0,0,0,0,0,2
5,0,0,0,0,0,0,0,0,0,0,2,0,0,0,0,0,0,2
2,2,2,0,2,2,0,0,0,0,0,2,0,0,0,0,0,0,2
2,0,0,0,0,2,0,0,0,0,0,2,2,2,2,2,0,0,2
2,0,0,0,0,2,0,0,0,0,0,2,4,4,2,2,0,0,2
2,0,0,0,0,2,0,0,0,0,0,2,4,4,2,2,0,0,2
2,0,0,0,0,2,0,0,0,0,0,2,4,4,4,7,0,0,2
2,0,0,0,0,2,5,0,0,5,5,2,4,4,4,7,0,0,2
2,2,2,2,2,2,0,0,0,0,0,2,2,2,2,2,2,2,2
endlayer

layer
2,2,2,2,2,2,2,2,2,2,2,2,2,2,2,2,2,2,2
2,0,0,0,0,0,0,0,0,0,0,2,0,0,0,0,0,0,2
2,0,0,0,0,0,0,0,0,0,0,2,0,0,0,0,0,0,2
2,0,0,0,0,0,0,0,0,0,0,0,0,0,0,0,0,0,2
2,0,0,0,0,0,0,0,0,0,0,0,0,0,0,0,0,0,2
2,0,0,0,0,0,0,0,0,0,0,2,0,0,0,0,0,0,2
2,2,2,2,2,2,2,0,0,2,2,2,0,0,0,0,0,0,2
0,0,0,0,0,0,0,0,0,0,0,2,0,0,0,0,0,0,2
0,0,0,0,0,0,0,0,0,0,0,2,0,0,0,0,0,0,2
0,0,0,0,0,0,0,0,0,0,0,2,0,0,0,0,0,0,2
0,0,0,0,0,0,0,0,0,0,0,2,0,0,0,0,0,0,2
0,0,0,0,0,0,0,0,0,0,0,2,0,0,0,0,0,0,2
2,2,2,0,2,2,0,0,0,0,0,2,0,0,0,0,0,0,2
2,0,0,0,0,2,0,0,0,0,0,2,4,4,2,2,0,0,2
2,0,0,0,0,2,0,0,0,0,0,2,4,4,2,2,0,0,2
2,0,0,0,0,2,0,0,0,0,0,2,4,4,2,2,0,0,2
2,0,0,0,0,2,0,0,0,0,0,2,7,7,0,0,0,0,2
2,0,0,0,0,2,10,0,0,0,0,2,7,7,0,0,0,0,2
2,2,2,2,2,2,0,0,0,0,0,2,2,2,2,2,2,2,2
endlayer

layer
2,2,2,2,2,2,2,2,2,2,2,2,2,2,2,2,2,2,2
2,4,4,4,4,4,4,4,4,4,4,2,4,4,4,4,4,4,2
2,4,4,4,4,4,4,4,4,4,4,2,4,4,4,4,4,4,2
2,4,4,4,4,4,4,4,4,4,4,2,4,4,4,4,4,4,2
2,4,4,4,4,4,4,4,4,4,4,2,4,4,4,4,4,4,2
2,4,4,4,4,4,4,4,4,4,4,2,4,4,4,4,4,4,2
2,2,2,2,2,2,2,2,2,2,2,2,4,4,4,4,4,4,2
0,0,0,0,0,0,0,0,0,0,0,2,4,4,4,4,4,4,2
0,0,0,0,0,0,0,0,0,0,0,2,4,4,4,4,4,4,2
0,0,0,0,0,0,0,0,0,0,0,2,4,4,4,4,4,4,2
0,0,0,0,0,0,0,0,0,0,0,2,4,4,4,4,4,4,2
0,0,0,0,0,0,0,0,0,0,0,2,4,4,4,4,4,4,2
2,2,2,2,2,2,0,0,0,0,0,2,4,4,4,4,4,4,2
2,4,4,4,4,2,0,0,0,0,0,2,4,4,4,4,4,4,2
2,4,4,4,4,2,0,0,0,0,0,2,7,7,4,4,0,0,2
2,4,4,4,4,2,0,0,0,0,0,2,0,0,4,4,0,0,2
2,4,4,4,4,2,0,0,0,0,0,2,0,0,0,0,0,0,2
2,4,4,4,4,2,0,0,0,0,0,2,0,0,0,0,0,0,2
2,2,2,2,2,2,0,0,0,0,0,2,2,2,2,2,2,2,2
endlayer

layer
5,5,5,5,5,5,5,5,5,5,5,5,5,5,5,5,5,5,5
5,0,0,0,0,0,0,0,0,0,0,0,0,0,0,0,0,0,5
5,0,0,0,0,0,0,0,0,0,0,0,0,0,0,0,0,0,5
5,0,0,0,0,0,0,0,0,0,0,0,0,0,0,0,0,0,5
5,0,0,0,0,0,0,0,0,0,0,0,0,0,0,0,0,0,5
5,0,0,0,0,0,0,0,0,0,0,0,0,0,0,0,0,0,5
5,5,5,5,5,5,5,5,5,5,5,5,0,0,0,0,0,0,5
0,0,0,0,0,0,0,0,0,0,0,5,0,0,0,0,0,0,5
0,0,0,0,0,0,0,0,0,0,0,5,0,0,0,0,0,0,5
0,0,0,0,0,0,0,0,0,0,0,5,0,0,0,0,0,0,5
0,0,0,0,0,0,0,0,0,0,0,5,0,0,0,0,0,0,5
0,0,0,0,0,0,0,0,0,0,0,5,0,0,0,0,0,0,5
0,0,0,0,0,0,0,0,0,0,0,5,0,0,0,0,0,0,5
0,0,0,0,0,0,0,0,0,0,0,5,0,0,0,5,5,5,5
0,0,0,0,0,0,0,0,0,0,0,5,0,0,0,5,0,0,5
0,0,0,0,0,0,0,0,0,0,0,5,0,0,5,5,0,0,5
0,0,0,0,0,0,0,0,0,0,0,5,0,0,0,0,0,0,5
0,0,0,0,0,0,0,0,0,0,0,5,0,0,0,0,0,0,5
0,0,0,0,0,0,0,0,0,0,0,5,5,5,5,5,5,5,5
endlayer